Workbook
Name celpeCEE: '[1]@Referência'!$K$16:$K$18
Name ListaSimNao: '[1]@Referência'!$A$30:$A$31
Name Modalidade: '[1]@Referência'!$J$2:$J$6
Name tipoCELPE: '[1]@Referência'!$N$14:$N$18

Sheet Tabela de Transferência
A1: Campo | B1: Página | C1: Endereço.tex | D1: chave | E1: valor
A2: Inserir Mome do RT | B2: Capa | C2: TCC_Final_CCEE.tex | D2: <<nomeRt>> | E2: =IFERROR(IF(UC_DADOS!B28="","",UC_DADOS!B28),"") -> Luiz Carlos Alves Lima
A3: NOME DA UNIDADE CONSUMIDORA DA PMS | B3: Capa | C3: TCC_Final_CCEE.tex | D3: <<nomeUc>> | E3: =IFERROR(IF(UC_DADOS!B1="","",UC_DADOS!B1),"")
A4: Data | B4: Capa | C4: TCC_Final_CCEE.tex | D4: <<data>> | E4: =IFERROR(IF(UC_DADOS!B8="","",UC_DADOS!B8),"")
A5: Inserir Mome do RT | B5: Contra Capa | C5: TCC_Final_CCEE.tex | D5: <<nomeRt>> | E5: =IFERROR(IF(E2="","",E2),"") -> Luiz Carlos Alves Lima
A6: NOME DA UNIDADE CONSUMIDORA DA PMS | B6: Contra Capa | C6: TCC_Final_CCEE.tex | D6: <<nomeUc>> | E6: =IFERROR(IF(E3="","",E3),"")
A7: Nome da UC | B7: Contra Capa | C7: TCC_Final_CCEE.tex | D7: <<nomeUc>> | E7: =IFERROR(IF(E6="","",E6),"")
A8: Data | B8: Contra Capa | C8: TCC_Final_CCEE.tex | D8: <<data>> | E8: =IFERROR(IF(E4="","",E4),"")
A9: Nome da Unidade | B9: 6 | C9: capitulo1.tex | D9: <<nomeUc>> | E9: =IFERROR(IF(E3="","",E3),"")
A10: Código da UC | B10: 6 | C10: capitulo1.tex | D10: <<codigoUc>> | E10: =IFERROR(IF(UC_DADOS!B2="","",UC_DADOS!B2),"")
A11: Tipo de Atividade | B11: 6 | C11: capitulo1.tex | D11: <<tipoAtividade>> | E11: =IFERROR(IF(UC_DADOS!B3="","",UC_DADOS!B3),"")
A12: Endereço Completo | B12: 6 | C12: capitulo1.tex | D12: <<endereco>> | E12: =IFERROR(IF(UC_DADOS!B4="","",UC_DADOS!B4),"")
A13: Responsável / Cargo | B13: 6 | C13: capitulo1.tex | D13: <<responsavel>> | E13: =IFERROR(IF(UC_DADOS!B6="","",UC_DADOS!B6),"")
A14: Telefone para Contato | B14: 6 | C14: capitulo1.tex | D14: <<telefone>> | E14: =IFERROR(IF(UC_DADOS!B7="","",UC_DADOS!B7),"")
A15: E-mail Institucional | B15: 6 | C15: capitulo1.tex | D15: <<email>> | E15: =IFERROR(IF(UC_DADOS!B9="","",UC_DADOS!B9),"")
A16: Adcionar Localidade | B16: 8 | C16: capitulo3.tex | D16: <<localidade>> | E16: =IFERROR(IF(UC_DADOS!B5="","",UC_DADOS!B5),"")
A17: Iluminação / Medida Proposta | B17: 11 | C17: capitulo4.tex | D17: <<propIluminacao>> | E17: =IFERROR(IF(TABELAS_RESUMO!B12="","",TABELAS_RESUMO!B12),"") -> Substituição por LED e sensores
A18: Climatização / Medida Proposta | B18: 11 | C18: capitulo4.tex | D18: <<propClimatizacao>> | E18: =IFERROR(IF(TABELAS_RESUMO!B13="","",TABELAS_RESUMO!B13),"") -> Troca de aparelhos de ar-condicionado e automação
A19: Motores / Medida Proposta | B19: 11 | C19: capitulo4.tex | D19: <<propMotores>> | E19: =IFERROR(IF(TABELAS_RESUMO!B14="","",TABELAS_RESUMO!B14),"") -> Substituição por motores de alto rendimento
A20: Refrigeração / Medida Proposta | B20: 11 | C20: capitulo4.tex | D20: <<propRefrigeracao>> | E20: =IFERROR(IF(TABELAS_RESUMO!B15="","",TABELAS_RESUMO!B15),"") -> Troca de refrigeradores comerciais ineficientes
A21: Fotovoltaico / Medida Proposta | B21: 11 | C21: capitulo4.tex | D21: <<propFotovoltaico>> | E21: =IFERROR(IF(TABELAS_RESUMO!B16="","",TABELAS_RESUMO!B16),"") -> Sistema conectado à rede (GD)
A22: Iluminação / Economia (MWh/ano) | B22: 11 | C22: capitulo4.tex | D22: <<iluEconomia>> | E22: =IFERROR(IF(TABELAS_RESUMO!C12="","",TABELAS_RESUMO!C12),"")
A23: Climatização / Economia (MWh/ano) | B23: 11 | C23: capitulo4.tex | D23: <<cliEconomia>> | E23: =IFERROR(IF(TABELAS_RESUMO!C13="","",TABELAS_RESUMO!C13),"")
A24: Motores / Economia (MWh/ano) | B24: 11 | C24: capitulo4.tex | D24: <<motEconomia>> | E24: =IFERROR(IF(TABELAS_RESUMO!C14="","",TABELAS_RESUMO!C14),"")
A25: Refrigeração / Economia (MWh/ano) | B25: 11 | C25: capitulo4.tex | D25: <<refEconomia>> | E25: =IFERROR(IF(TABELAS_RESUMO!C15="","",TABELAS_RESUMO!C15),"")
A26: Fotovoltaico / Economia (MWh/ano) | B26: 11 | C26: capitulo4.tex | D26: <<fotEconomia>> | E26: =IFERROR(IF(TABELAS_RESUMO!C16="","",TABELAS_RESUMO!C16),"")
A27: Total / Economia (MWh/ano) | B27: 11 | C27: capitulo4.tex | D27: <<totEconomia>> | E27: =IFERROR(IF(TABELAS_RESUMO!C17="","",TABELAS_RESUMO!C17),"")
A28: Iluminação / Invest. Total (R$) | B28: 11 | C28: capitulo4.tex | D28: <<iluInvestimento>> | E28: =IFERROR(IF(TABELAS_RESUMO!D12="","",TABELAS_RESUMO!D12),"")
A29: Climatização / Invest. Total (R$) | B29: 11 | C29: capitulo4.tex | D29: <<cliInvestimento>> | E29: =IFERROR(IF(TABELAS_RESUMO!D13="","",TABELAS_RESUMO!D13),"")
A30: Motores / Invest. Total (R$) | B30: 11 | C30: capitulo4.tex | D30: <<motInvestimento>> | E30: =IFERROR(IF(TABELAS_RESUMO!D14="","",TABELAS_RESUMO!D14),"")
A31: Refrigeração / Invest. Total (R$) | B31: 11 | C31: capitulo4.tex | D31: <<refInvestimento>> | E31: =IFERROR(IF(TABELAS_RESUMO!D15="","",TABELAS_RESUMO!D15),"")
A32: Fotovoltaico / Invest. Total (R$) | B32: 11 | C32: capitulo4.tex | D32: <<fotInvestimento>> | E32: =IFERROR(IF(TABELAS_RESUMO!D16="","",TABELAS_RESUMO!D16),"")
A33: Total / Invest. Total (R$) | B33: 11 | C33: capitulo4.tex | D33: <<totInvestimento>> | E33: =IFERROR(IF(TABELAS_RESUMO!D17="","",TABELAS_RESUMO!D17),"")
A34: Iluminação / PB | B34: 11 | C34: capitulo4.tex | D34: <<iluPayBack>> | E34: =IFERROR(IF(TABELAS_RESUMO!E12="","",TABELAS_RESUMO!E12),"")
A35: Climatização / PB | B35: 11 | C35: capitulo4.tex | D35: <<cliPayBack>> | E35: =IFERROR(IF(TABELAS_RESUMO!E13="","",TABELAS_RESUMO!E13),"")
A36: Motores / PB | B36: 11 | C36: capitulo4.tex | D36: <<motPayBack>> | E36: =IFERROR(IF(TABELAS_RESUMO!E14="","",TABELAS_RESUMO!E14),"")
A37: Refrigeração / PB | B37: 11 | C37: capitulo4.tex | D37: <<refPayBack>> | E37: =IFERROR(IF(TABELAS_RESUMO!E15="","",TABELAS_RESUMO!E15),"")
A38: Fotovoltaico / PB | B38: 11 | C38: capitulo4.tex | D38: <<fotPayBack>> | E38: =IFERROR(IF(TABELAS_RESUMO!E16="","",TABELAS_RESUMO!E16),"")
A39: Total / PB | B39: 11 | C39: capitulo4.tex | D39: <<totPayBack>> | E39: =IFERROR(IF(TABELAS_RESUMO!E17="","",TABELAS_RESUMO!E17),"")
A40: Nome da Unidade | B40: 12 | C40: capitulo5.tex | D40: <<nomeUc>> | E40: =IFERROR(IF(E3="","",E3),"")
...

Sheet UC_DADOS
A1: Nome da Unidade | B1: =_xlfn.XLOOKUP(MAX(FATURAS!M:M), FATURAS!M:M, FATURAS!F:F,,-1) -> #N/A
A2: Código da UC | B2: =_xlfn.XLOOKUP(MAX(FATURAS!M:M), FATURAS!M:M, FATURAS!AA:AA,,-1) -> #N/A
A3: Tipo de Atividade
A4: Endereço Completo
A5: Localidade
A6: Responsável / Cargo
A7: Telefone para Contato
A8: Data
A9: E-mail institucional
A12: Alunos
A13: Consumo médio mensal (kWh/mês) | B13: =AVERAGE(FATURAS!AF:AF) -> #DIV/0!
A14: Consumo específico estimado | B14: =(B13/B12) -> #DIV/0!
A15: Consumo específico Típico | B15: =IF(A12="Alunos","4 a 8 kWh/Alunos/mês",IF(A12="Pacientes","10 a 18 kWh/Pacientes/mês",IF(A12="Leitos","250 a 400 kWh/Leito/mês",IF(A12="Funcionários","8 a 12 kWh/Funcionários/mês",IF(A12="Visitantes","3 a 7 kWh/Visitantes/mês",""))))) -> 4 a 8 kWh/Alunos/mês
A16: Tipo de Edificação | B16: =IF(A12="Alunos","Escola pública (fundamental)",IF(A12="Pacientes","Unidade básica de saúde",IF(A12="Leitos","Hospital de médio porte",IF(A12="Funcionários","Prédio administrativo",IF(A12="Visitantes","Unidade esportiva / ginásio",""))))) -> Escola pública (fundamental)
A18: Modalidade tarifária | B18: =_xlfn.TEXTBEFORE(_xlfn.XLOOKUP(MAX(FATURAS!M:M),FATURAS!M:M,FATURAS!Y:Y,,-1)," ",3) -> #N/A
A19: Demanda contratada | B19: =IF(ISNUMBER(_xlfn.XLOOKUP(MAX(FATURAS!M:M),FATURAS!M:M,FATURAS!U:U,,-1)),_xlfn.XLOOKUP(MAX(FATURAS!M:M),FATURAS!M:M,FATURAS!U:U,,-1),_xlfn.XLOOKUP(MAX(FATURAS!M:M),FATURAS!M:M,FATURAS!V:V,,-1)&" NP e "&_xlfn.XLOOKUP(MAX(FATURAS!M:M),FATURAS!M:M,FATURAS!W:W,,-1)&" FP") -> #N/A
A20: Número da instalação na distribuidora | B20: =_xlfn.XLOOKUP(MAX(FATURAS!M:M),FATURAS!M:M,FATURAS!AB:AB) -> #N/A
A21: Código da unidade consumidora | B21: =B2 -> #N/A
A22: Classe de consumo | B22: =_xlfn.TEXTAFTER(_xlfn.XLOOKUP(MAX(FATURAS!M:M),FATURAS!M:M,FATURAS!Y:Y,,-1)," ",3) -> #N/A
A28: Resnposável Técnico | B28: Luiz Carlos Alves Lima
A29: Grupo | B29: =IF(LEFT(FATURAS!X2,1)="A","Grupo A",IF(LEFT(FATURAS!X2,1)="B","Grupo B",""))
A32: Preço da Energia do Ultimo Mês | B32: =SUMIF(FATURAS!M:M,MAX(FATURAS!M:M),FATURAS!E:E) -> 0
A33: Distribuidora de Energia | B33: =FATURAS!J2 -> 0
A34: Maior Consumo Registrado (kWh) | B34: =MAX(G37:G48) -> 0
A35: Mês/Ano do Maior Consumo | B35: =INDEX(D37:D48,MATCH(MAX(G37:G48),G37:G48,0))
A36: Mês/Ano do Menor Consumo | B36: =INDEX(D37:D48,MATCH(MIN(G37:G48),G37:G48,0)) | D36: Mês / Ano | E36: Consumo Ponta (kWh) | F36: Consumo Fora Ponta (kWh) | G36: Consumo Total (kW) | H36: Demanda Ponta (kW) | I36: Demanda Fora Ponta (kW) | J36: Despesa C/ Energia
A37: Custo anual de energia elétrica (R$) | B37: =SUMIFS(FATURAS!E:E,FATURAS!M:M,">="&DATE(YEAR(TODAY()),1,1),FATURAS!M:M,"<="&DATE(YEAR(TODAY()),12,31)) -> 0 | D37: =IFERROR(TEXT(SMALL(_xlfn.UNIQUE(FATURAS!M:M),1),"MMM/AA"),"") | E37: =SUMIFS(FATURAS!AQ:AQ, FATURAS!M:M, SMALL(_xlfn.UNIQUE(FATURAS!M:M),1)) -> 0 | F37: =SUMIFS(FATURAS!AR:AR, FATURAS!M:M, SMALL(_xlfn.UNIQUE(FATURAS!M:M),1)) -> 0 | G37: =SUM(E37+F37) -> 0 | H37: {=SUMPRODUCT( (FATURAS!M2:M5000=SMALL(_xlfn.UNIQUE(FATURAS!M2:M5000),1))* FATURAS!AU2:AU5000* IF(ISNUMBER(FATURAS!BN2:BN5000),1+(FATURAS!BN2:BN5000/100),1))} -> #NUM! | I37: {=SUMPRODUCT((FATURAS!M2:M5000=SMALL(_xlfn.UNIQUE(FATURAS!M2:M5000),1))*FATURAS!AV2:AV5000*IF(ISNUMBER(FATURAS!BN2:BN5000),1+(FATURAS!BN2:BN5000/100),1))} -> #NUM! | J37: =SUMIFS(FATURAS!E:E, FATURAS!M:M, SMALL(_xlfn.UNIQUE(FATURAS!M:M),1)) -> 0
A38: Fator de carga médio estimado | B38: {=IFERROR(SUMPRODUCT(IFERROR(FATURAS!AD2:AD13/(FATURAS!AV2:AV13*FATURAS!Q2:Q13*24),0))/SUMPRODUCT((FATURAS!AV2:AV13<>0)*(FATURAS!Q2:Q13<>0)),0)} -> 0 | D38: =IFERROR(TEXT(SMALL(_xlfn.UNIQUE(FATURAS!M:M),2),"MMM/AA"),"") | E38: =SUMIFS(FATURAS!AQ:AQ, FATURAS!M:M, SMALL(_xlfn.UNIQUE(FATURAS!M:M),2)) -> 0 | F38: =SUMIFS(FATURAS!AR:AR, FATURAS!M:M, SMALL(_xlfn.UNIQUE(FATURAS!M:M),2)) -> 0 | G38: =SUM(E38+F38) -> 0 | H38: {=SUMPRODUCT( (FATURAS!M2:M5000=SMALL(_xlfn.UNIQUE(FATURAS!M2:M5000),2))* FATURAS!AU2:AU5000* IF(ISNUMBER(FATURAS!BN2:BN5000),1+(FATURAS!BN2:BN5000/100),1))} -> #NUM! | I38: {=SUMPRODUCT((FATURAS!M2:M5000=SMALL(_xlfn.UNIQUE(FATURAS!M2:M5000),2))*FATURAS!AV2:AV5000*IF(ISNUMBER(FATURAS!BN2:BN5000),1+(FATURAS!BN2:BN5000/100),1))} -> #NUM! | J38: =SUMIFS(FATURAS!E:E, FATURAS!M:M, SMALL(_xlfn.UNIQUE(FATURAS!M:M),2)) -> 0
A39: Faturas Disponíveis | B39: Todas as faturas disponíveis no histórico de análise dos últimos 12 meses. | D39: =IFERROR(TEXT(SMALL(_xlfn.UNIQUE(FATURAS!M:M),3),"MMM/AA"),"") | E39: =SUMIFS(FATURAS!AQ:AQ, FATURAS!M:M, SMALL(_xlfn.UNIQUE(FATURAS!M:M),3)) -> 0 | F39: =SUMIFS(FATURAS!AR:AR, FATURAS!M:M, SMALL(_xlfn.UNIQUE(FATURAS!M:M),3)) -> 0 | G39: =SUM(E39+F39) -> 0 | H39: {=SUMPRODUCT( (FATURAS!M2:M5000=SMALL(_xlfn.UNIQUE(FATURAS!M2:M5000),3))* FATURAS!AU2:AU5000* IF(ISNUMBER(FATURAS!BN2:BN5000),1+(FATURAS!BN2:BN5000/100),1))} -> #NUM! | I39: {=SUMPRODUCT((FATURAS!M2:M5000=SMALL(_xlfn.UNIQUE(FATURAS!M2:M5000),3))*FATURAS!AV2:AV5000*IF(ISNUMBER(FATURAS!BN2:BN5000),1+(FATURAS!BN2:BN5000/100),1))} -> #NUM! | J39: =SUMIFS(FATURAS!E:E, FATURAS!M:M, SMALL(_xlfn.UNIQUE(FATURAS!M:M),3)) -> 0
A40: Fator de carga Ponta | B40: =AVERAGEIFS(FATURAS!BL:BL,FATURAS!M:M,">="&DATE(YEAR(TODAY()),1,1),FATURAS!M:M,"<="&DATE(YEAR(TODAY()),12,31)) -> #DIV/0! | D40: =IFERROR(TEXT(SMALL(_xlfn.UNIQUE(FATURAS!M:M),4),"MMM/AA"),"") | E40: =SUMIFS(FATURAS!AQ:AQ, FATURAS!M:M, SMALL(_xlfn.UNIQUE(FATURAS!M:M),4)) -> 0 | F40: =SUMIFS(FATURAS!AR:AR, FATURAS!M:M, SMALL(_xlfn.UNIQUE(FATURAS!M:M),4)) -> 0 | G40: =SUM(E40+F40) -> 0 | H40: {=SUMPRODUCT( (FATURAS!M2:M5000=SMALL(_xlfn.UNIQUE(FATURAS!M2:M5000),4))* FATURAS!AU2:AU5000* IF(ISNUMBER(FATURAS!BN2:BN5000),1+(FATURAS!BN2:BN5000/100),1))} -> #NUM! | I40: {=SUMPRODUCT((FATURAS!M2:M5000=SMALL(_xlfn.UNIQUE(FATURAS!M2:M5000),4))*FATURAS!AV2:AV5000*IF(ISNUMBER(FATURAS!BN2:BN5000),1+(FATURAS!BN2:BN5000/100),1))} -> #NUM! | J40: =SUMIFS(FATURAS!E:E, FATURAS!M:M, SMALL(_xlfn.UNIQUE(FATURAS!M:M),4)) -> 0
A41: Fator de carga Fora Ponta | B41: =AVERAGEIFS(FATURAS!BM:BM,FATURAS!M:M,">="&DATE(YEAR(TODAY()),1,1),FATURAS!M:M,"<="&DATE(YEAR(TODAY()),12,31)) -> #DIV/0! | D41: =IFERROR(TEXT(SMALL(_xlfn.UNIQUE(FATURAS!M:M),5),"MMM/AA"),"") | E41: =SUMIFS(FATURAS!AQ:AQ, FATURAS!M:M, SMALL(_xlfn.UNIQUE(FATURAS!M:M),5)) -> 0 | F41: =SUMIFS(FATURAS!AR:AR, FATURAS!M:M, SMALL(_xlfn.UNIQUE(FATURAS!M:M),5)) -> 0 | G41: =SUM(E41+F41) -> 0 | H41: {=SUMPRODUCT( (FATURAS!M2:M5000=SMALL(_xlfn.UNIQUE(FATURAS!M2:M5000),5))* FATURAS!AU2:AU5000* IF(ISNUMBER(FATURAS!BN2:BN5000),1+(FATURAS!BN2:BN5000/100),1))} -> #NUM! | I41: {=SUMPRODUCT((FATURAS!M2:M5000=SMALL(_xlfn.UNIQUE(FATURAS!M2:M5000),5))*FATURAS!AV2:AV5000*IF(ISNUMBER(FATURAS!BN2:BN5000),1+(FATURAS!BN2:BN5000/100),1))} -> #NUM! | J41: =SUMIFS(FATURAS!E:E, FATURAS!M:M, SMALL(_xlfn.UNIQUE(FATURAS!M:M),5)) -> 0
A42: Fator de Potencia | B42: {=SUMPRODUCT((YEAR(FATURAS!M2:M13)=YEAR(TODAY()))*FATURAS!AD2:AD13)/SQRT(SUMPRODUCT((YEAR(FATURAS!M2:M13)=YEAR(TODAY()))*FATURAS!AD2:AD13)^2+SUMPRODUCT((YEAR(FATURAS!M2:M13)=YEAR(TODAY()))*FATURAS!BC2:BC13)^2)} -> #DIV/0! | D42: =IFERROR(TEXT(SMALL(_xlfn.UNIQUE(FATURAS!M:M),6),"MMM/AA"),"") | E42: =SUMIFS(FATURAS!AQ:AQ, FATURAS!M:M, SMALL(_xlfn.UNIQUE(FATURAS!M:M),6)) -> 0 | F42: =SUMIFS(FATURAS!AR:AR, FATURAS!M:M, SMALL(_xlfn.UNIQUE(FATURAS!M:M),6)) -> 0 | G42: =SUM(E42+F42) -> 0 | H42: {=SUMPRODUCT( (FATURAS!M2:M5000=SMALL(_xlfn.UNIQUE(FATURAS!M2:M5000),6))* FATURAS!AU2:AU5000* IF(ISNUMBER(FATURAS!BN2:BN5000),1+(FATURAS!BN2:BN5000/100),1))} -> #NUM! | I42: {=SUMPRODUCT((FATURAS!M2:M5000=SMALL(_xlfn.UNIQUE(FATURAS!M2:M5000),6))*FATURAS!AV2:AV5000*IF(ISNUMBER(FATURAS!BN2:BN5000),1+(FATURAS!BN2:BN5000/100),1))} -> #NUM! | J42: =SUMIFS(FATURAS!E:E, FATURAS!M:M, SMALL(_xlfn.UNIQUE(FATURAS!M:M),6)) -> 0
A43: Custo Médio Unitário (R$/kWh) | B43: {=SUMPRODUCT((YEAR(FATURAS!M2:M13)=YEAR(TODAY()))*FATURAS!AF2:AF13)/SUMPRODUCT((YEAR(FATURAS!M2:M13)=YEAR(TODAY()))*FATURAS!E2:E13)} -> #DIV/0! | D43: =IFERROR(TEXT(SMALL(_xlfn.UNIQUE(FATURAS!M:M),7),"MMM/AA"),"") | E43: =SUMIFS(FATURAS!AQ:AQ, FATURAS!M:M, SMALL(_xlfn.UNIQUE(FATURAS!M:M),7)) -> 0 | F43: =SUMIFS(FATURAS!AR:AR, FATURAS!M:M, SMALL(_xlfn.UNIQUE(FATURAS!M:M),7)) -> 0 | G43: =SUM(E43+F43) -> 0 | H43: {=SUMPRODUCT( (FATURAS!M2:M5000=SMALL(_xlfn.UNIQUE(FATURAS!M2:M5000),7))* FATURAS!AU2:AU5000* IF(ISNUMBER(FATURAS!BN2:BN5000),1+(FATURAS!BN2:BN5000/100),1))} -> #NUM! | I43: {=SUMPRODUCT((FATURAS!M2:M5000=SMALL(_xlfn.UNIQUE(FATURAS!M2:M5000),7))*FATURAS!AV2:AV5000*IF(ISNUMBER(FATURAS!BN2:BN5000),1+(FATURAS!BN2:BN5000/100),1))} -> #NUM! | J43: =SUMIFS(FATURAS!E:E, FATURAS!M:M, SMALL(_xlfn.UNIQUE(FATURAS!M:M),7)) -> 0
A44: ="Consumo por " & A12 & " (kWh/mês)" -> Consumo por Alunos (kWh/mês) | B44: {=SUMPRODUCT((YEAR(FATURAS!M2:M13)=YEAR(TODAY()))*FATURAS!AD2:AD13)/(12*B12)} -> #DIV/0! | D44: =IFERROR(TEXT(SMALL(_xlfn.UNIQUE(FATURAS!M:M),8),"MMM/AA"),"") | E44: =SUMIFS(FATURAS!AQ:AQ, FATURAS!M:M, SMALL(_xlfn.UNIQUE(FATURAS!M:M),8)) -> 0 | F44: =SUMIFS(FATURAS!AR:AR, FATURAS!M:M, SMALL(_xlfn.UNIQUE(FATURAS!M:M),8)) -> 0 | G44: =SUM(E44+F44) -> 0 | H44: {=SUMPRODUCT( (FATURAS!M2:M5000=SMALL(_xlfn.UNIQUE(FATURAS!M2:M5000),8))* FATURAS!AU2:AU5000* IF(ISNUMBER(FATURAS!BN2:BN5000),1+(FATURAS!BN2:BN5000/100),1))} -> #NUM! | I44: {=SUMPRODUCT((FATURAS!M2:M5000=SMALL(_xlfn.UNIQUE(FATURAS!M2:M5000),8))*FATURAS!AV2:AV5000*IF(ISNUMBER(FATURAS!BN2:BN5000),1+(FATURAS!BN2:BN5000/100),1))} -> #NUM! | J44: =SUMIFS(FATURAS!E:E, FATURAS!M:M, SMALL(_xlfn.UNIQUE(FATURAS!M:M),8)) -> 0
D45: =IFERROR(TEXT(SMALL(_xlfn.UNIQUE(FATURAS!M:M),9),"MMM/AA"),"") | E45: =SUMIFS(FATURAS!AQ:AQ, FATURAS!M:M, SMALL(_xlfn.UNIQUE(FATURAS!M:M),9)) -> 0 | F45: =SUMIFS(FATURAS!AR:AR, FATURAS!M:M, SMALL(_xlfn.UNIQUE(FATURAS!M:M),9)) -> 0 | G45: =SUM(E45+F45) -> 0 | H45: {=SUMPRODUCT( (FATURAS!M2:M5000=SMALL(_xlfn.UNIQUE(FATURAS!M2:M5000),9))* FATURAS!AU2:AU5000* IF(ISNUMBER(FATURAS!BN2:BN5000),1+(FATURAS!BN2:BN5000/100),1))} -> #NUM! | I45: {=SUMPRODUCT((FATURAS!M2:M5000=SMALL(_xlfn.UNIQUE(FATURAS!M2:M5000),9))*FATURAS!AV2:AV5000*IF(ISNUMBER(FATURAS!BN2:BN5000),1+(FATURAS!BN2:BN5000/100),1))} -> #NUM! | J45: =SUMIFS(FATURAS!E:E, FATURAS!M:M, SMALL(_xlfn.UNIQUE(FATURAS!M:M),9)) -> 0
D46: =IFERROR(TEXT(SMALL(_xlfn.UNIQUE(FATURAS!M:M),10),"MMM/AA"),"") | E46: =SUMIFS(FATURAS!AQ:AQ, FATURAS!M:M, SMALL(_xlfn.UNIQUE(FATURAS!M:M),10)) -> 0 | F46: =SUMIFS(FATURAS!AR:AR, FATURAS!M:M, SMALL(_xlfn.UNIQUE(FATURAS!M:M),10)) -> 0 | G46: =SUM(E46+F46) -> 0 | H46: {=SUMPRODUCT( (FATURAS!M2:M5000=SMALL(_xlfn.UNIQUE(FATURAS!M2:M5000),10))* FATURAS!AU2:AU5000* IF(ISNUMBER(FATURAS!BN2:BN5000),1+(FATURAS!BN2:BN5000/100),1))} -> #NUM! | I46: {=SUMPRODUCT((FATURAS!M2:M5000=SMALL(_xlfn.UNIQUE(FATURAS!M2:M5000),10))*FATURAS!AV2:AV5000*IF(ISNUMBER(FATURAS!BN2:BN5000),1+(FATURAS!BN2:BN5000/100),1))} -> #NUM! | J46: =SUMIFS(FATURAS!E:E, FATURAS!M:M, SMALL(_xlfn.UNIQUE(FATURAS!M:M),10)) -> 0
D47: =IFERROR(TEXT(SMALL(_xlfn.UNIQUE(FATURAS!M:M),11),"MMM/AA"),"") | E47: =SUMIFS(FATURAS!AQ:AQ, FATURAS!M:M, SMALL(_xlfn.UNIQUE(FATURAS!M:M),11)) -> 0 | F47: =SUMIFS(FATURAS!AR:AR, FATURAS!M:M, SMALL(_xlfn.UNIQUE(FATURAS!M:M),11)) -> 0 | G47: =SUM(E47+F47) -> 0 | H47: {=SUMPRODUCT( (FATURAS!M2:M5000=SMALL(_xlfn.UNIQUE(FATURAS!M2:M5000),11))* FATURAS!AU2:AU5000* IF(ISNUMBER(FATURAS!BN2:BN5000),1+(FATURAS!BN2:BN5000/100),1))} -> #NUM! | I47: {=SUMPRODUCT((FATURAS!M2:M5000=SMALL(_xlfn.UNIQUE(FATURAS!M2:M5000),11))*FATURAS!AV2:AV5000*IF(ISNUMBER(FATURAS!BN2:BN5000),1+(FATURAS!BN2:BN5000/100),1))} -> #NUM! | J47: =SUMIFS(FATURAS!E:E, FATURAS!M:M, SMALL(_xlfn.UNIQUE(FATURAS!M:M),11)) -> 0
D48: =IFERROR(TEXT(SMALL(_xlfn.UNIQUE(FATURAS!M:M),12),"MMM/AA"),"") | E48: =SUMIFS(FATURAS!AQ:AQ, FATURAS!M:M, SMALL(_xlfn.UNIQUE(FATURAS!M:M),12)) -> 0 | F48: =SUMIFS(FATURAS!AR:AR, FATURAS!M:M, SMALL(_xlfn.UNIQUE(FATURAS!M:M),12)) -> 0 | G48: =SUM(E48+F48) -> 0 | H48: {=SUMPRODUCT( (FATURAS!M2:M5000=SMALL(_xlfn.UNIQUE(FATURAS!M2:M5000),12))* FATURAS!AU2:AU5000* IF(ISNUMBER(FATURAS!BN2:BN5000),1+(FATURAS!BN2:BN5000/100),1))} -> #NUM! | I48: {=SUMPRODUCT((FATURAS!M2:M5000=SMALL(_xlfn.UNIQUE(FATURAS!M2:M5000),12))*FATURAS!AV2:AV5000*IF(ISNUMBER(FATURAS!BN2:BN5000),1+(FATURAS!BN2:BN5000/100),1))} -> #NUM! | J48: =SUMIFS(FATURAS!E:E, FATURAS!M:M, SMALL(_xlfn.UNIQUE(FATURAS!M:M),12)) -> 0
D49: TOTAIS | G49: =SUM(G37:G48) -> 0
G50: =G49/1000 -> 0

Sheet FATURAS
A1: id_fatura | B1: status_pagamento | C1: status_leitura | D1: nome_empresa_cliente | E1: valor_total_em_reais | F1: nome_uc | G1: tipo_uc | H1: nome_grupo_uc | I1: tipo_instalacao | J1: nome_distribuidora_energia | K1: data_emissao | L1: data_vencimento | M1: periodo_referencia | N1: proxima_leitura_fatura | O1: leitura_atual_fatura | P1: ultima_leitura_fatura | Q1: numero_dias | R1: consumo_minimo | S1: id_ultima_fatura | T1: periodo_referencia_ultima_fatura | U1: demanda_contratada | V1: demanda_contratada_ponta | W1: demanda_contratada_fora_ponta | X1: nome_classe | Y1: descricao_classe | Z1: tipo_fornecimento | AA1: codigo_cliente | AB1: codigo_instalacao | AC1: consumo_total | AD1: consumo_total_com_perda_transformacao | AE1: consumo_compensado_total | AF1: consumo_faturado_total | AG1: energia_total_injetada | AH1: consumo_ponta | AI1: consumo_ponta_com_perda_transformacao | AJ1: consumo_fora_ponta | AK1: consumo_fora_ponta_com_perda_transformacao | AL1: consumo_intermediario | AM1: consumo_intermediario_com_perda_transformacao | AN1: consumo_compensado_ponta | AO1: consumo_compensado_fora_ponta | AP1: consumo_compensado_intermediário | AQ1: consumo_faturado_ponta | AR1: consumo_faturado_fora_ponta | AS1: consumo_faturado_intermediario | AT1: demanda_maxima | AU1: demanda_maxima_ponta | AV1: demanda_maxima_fora_ponta | AW1: demanda_de_ultrapassagem | AX1: demanda_de_ultrapassagem_ponta | AY1: demanda_de_ultrapassagem_fora_ponta | AZ1: demanda_faturada | BA1: demanda_faturada_ponta | BB1: demanda_faturada_fora_ponta | BC1: consumo_reativo_total | BD1: consumo_reativo_ponta | BE1: consumo_reativo_fora_ponta | BF1: consumo_reativo_excedente_total | BG1: consumo_reativo_excedente_ponta | BH1: consumo_reativo_excedente_fora_ponta | BI1: demanda_reativa_excedente | BJ1: demanda_reativa_excedente_ponta | BK1: demanda_reativa_excedente_fora_ponta | BL1: fator_carga_ponta | BM1: fator_carga_fora_ponta | BN1: percentual_perda_transformacao | BO1: creditos_acumulados_anterior | BP1: creditos_acumulados | BQ1: movimentacao_creditos_mes | BR1: tarifa_consumo_ponta | BS1: tarifa_consumo_fora_ponta | BT1: tarifa_consumo_intermediario | BU1: tarifa_consumo_convencional | BV1: tarifa_demanda_maxima | BW1: tarifa_demanda_de_ultrapassagem | BX1: tarifa_demanda_de_ultrapassagem_ponta | BY1: tarifa_demanda_de_ultrapassagem_fora_ponta | BZ1: tarifa_demanda_maxima_ponta | CA1: tarifa_demanda_maxima_fora_ponta | CB1: tarifa_consumo_reativo_excedente | CC1: tarifa_demanda_reativa_excedente | CD1: tarifa_calculada_demanda_ultrapassada | CE1: tarifa_calculada_demanda_de_ultrapassagem_ponta | CF1: tarifa_calculada_demanda_de_ultrapassagem_fora_ponta | CG1: tarifa_efetiva_de_consumo | CH1: valor_total_icms | CI1: base_calculo_icms | CJ1: aliquota_icms | CK1: valor_total_pis | CL1: base_calculo_pis | CM1: aliquota_pis | CN1: valor_total_cofins | CO1: base_calculo_cofins | CP1: aliquota_cofins | CQ1: numero_nota_fiscal | CR1: url_nota_fiscal | CS1: chave_acesso_nota_fiscal | CT1: arquivo_anexo | CU1: potencial_de_economia_mensal | CV1: potencial_de_economia_anual | CW1: potencial_de_economia_12_meses

Sheet Sistemas de Cond. Ambiental
A1: UNIDADE CONSUMIDORA | D1: SITUAÇÃO ATUAL | V1: SISTEMA PROPOSTO | AN1: RESULTADOS ESPERADOS | AQ1: RESULTADO AUTOMAÇÃO (10%) | AR1: AUTOMAÇÃO + TROCA DE EQUIPAMENTO
A2: Unidade consumidora (Número da conta contrato) | B2: Pavimento | C2: Ambiente | D2: Descrição do sistema | E2: Tipo de equipamento / tecnologia | F2: Classificação Inmetro | G2: Potência nominal de refrigeração (BTU/h) | H2: Coefiente de eficiência energética (W/W) | I2: Quantidade | J2: Potência instalada (kW) | K2: Fator de utilização | L2: Potência média utilizada (kW) | M2: Funcionamento (h/dia) | N2: Funcionamento (h/ano) | O2: Meses no ano, de utilização do Sistema | P2: Dias no mês, de utilização do Sistema | Q2: Dias úteis no mês, de utilização do Sistema | R2: Horas por dia, de utilização do Sistema no horário de Ponta (horas) | S2: Fator de coincidência na ponta | T2: Energia consumida (MWh/ano) | U2: Demanda média na ponta (kW) | V2: Tipo de equipamento / tecnologia | W2: Classificação Inmetro | X2: Potência nominal de refrigeração (BTU/h) | Y2: Coefiente de eficiência energética (W/W) | Z2: Preço Unitário (R$) | AA2: Quantidade | AB2: Potência instalada (kW) | AC2: Fator de utilização | AD2: Potência média utilizada (kW) | AE2: Funcionamento (h/dia) | AF2: Funcionamento (h/ano) | AG2: Meses no ano, de utilização do Sistema no horário de Ponta (meses) | AH2: Dias úteis no mês, de utilização do Sistema no horário de Ponta (dia) | AI2: Horas por dia, de utilização do Sistema no horário de Ponta (horas) | AJ2: Fator de coincidência na ponta | AK2: Energia consumida (MWh/ano) | AL2: Demanda média na ponta (kW) | AM2: Redução de demanda na ponta (kW) | AN2: Energia economizada (MWh/ano) | AO2: Investimento (R$) | AP2: Redução de consumo proposto em relação ao consumo total da UC (%) | AQ2: Energia economizada (MWh/ano) | AR2: Energia economizada (MWh/ano)
A3: =IF(UC_DADOS!$B$2=0,"",UC_DADOS!$B$2) -> #N/A | J3: =IF(H3=0,0,((G3*0.293*I3)/(1000*H3))) -> 0 | K3: 0.7 | L3: =J3*K3 -> 0 | N3: =M3*O3*P3 -> 0 | Q3: 21.25 | S3: =O3*Q3*R3/765 -> 0 | T3: =N3*L3/1000 -> 0 | U3: =S3*L3 -> 0 | V3: {=IF(F3="A",E3,IFERROR(INDEX('EQUIPAMENTOS_EFICIENTES (BDD)'!G:G,MATCH(1,('EQUIPAMENTOS_EFICIENTES (BDD)'!G:G=E3)*('EQUIPAMENTOS_EFICIENTES (BDD)'!I:I=_xlfn.MINIFS('EQUIPAMENTOS_EFICIENTES (BDD)'!I:I,'EQUIPAMENTOS_EFICIENTES (BDD)'!G:G,E3,'EQUIPAMENTOS_EFICIENTES (BDD)'!I:I,">="&G3)),0)),"Substituição não encontrada"))} -> 0 | W3: {=IF(F3="A",F3,IFERROR(INDEX('EQUIPAMENTOS_EFICIENTES (BDD)'!H:H,MATCH(1,('EQUIPAMENTOS_EFICIENTES (BDD)'!G:G=E3)*('EQUIPAMENTOS_EFICIENTES (BDD)'!I:I=_xlfn.MINIFS('EQUIPAMENTOS_EFICIENTES (BDD)'!I:I,'EQUIPAMENTOS_EFICIENTES (BDD)'!G:G,E3,'EQUIPAMENTOS_EFICIENTES (BDD)'!I:I,">="&G3)),0)),"Substituição não encontrada"))} -> 0 | X3: {=IF(F3="A",G3,IFERROR(INDEX('EQUIPAMENTOS_EFICIENTES (BDD)'!I:I,MATCH(1,('EQUIPAMENTOS_EFICIENTES (BDD)'!G:G=E3)*('EQUIPAMENTOS_EFICIENTES (BDD)'!I:I=_xlfn.MINIFS('EQUIPAMENTOS_EFICIENTES (BDD)'!I:I,'EQUIPAMENTOS_EFICIENTES (BDD)'!G:G,E3,'EQUIPAMENTOS_EFICIENTES (BDD)'!I:I,">="&G3)),0)),"Substituição não encontrada"))} -> 0 | Y3: {=IF(F3="A",H3,IFERROR(INDEX('EQUIPAMENTOS_EFICIENTES (BDD)'!J:J,MATCH(1,('EQUIPAMENTOS_EFICIENTES (BDD)'!G:G=E3)*('EQUIPAMENTOS_EFICIENTES (BDD)'!I:I=_xlfn.MINIFS('EQUIPAMENTOS_EFICIENTES (BDD)'!I:I,'EQUIPAMENTOS_EFICIENTES (BDD)'!G:G,E3,'EQUIPAMENTOS_EFICIENTES (BDD)'!I:I,">="&G3)),0)),"Substituição não encontrada"))} -> 0 | Z3: {=IFERROR(INDEX('EQUIPAMENTOS_EFICIENTES (BDD)'!K:K,MATCH(1,('EQUIPAMENTOS_EFICIENTES (BDD)'!G:G=E3)*('EQUIPAMENTOS_EFICIENTES (BDD)'!I:I=_xlfn.MINIFS('EQUIPAMENTOS_EFICIENTES (BDD)'!I:I,'EQUIPAMENTOS_EFICIENTES (BDD)'!G:G,E3,'EQUIPAMENTOS_EFICIENTES (BDD)'!I:I,">="&G3)),0)),"")} -> 0 | AA3: =I3 -> 0 | AB3: =IF(Y3=0,0,((X3*0.293*AA3)/(1000*Y3))) -> 0 | AC3: =K3 -> 0.7 | AD3: =AB3*AC3 -> 0 | AE3: =M3 -> 0 | AF3: =N3 -> 0 | AG3: =O3 -> 0 | AH3: =Q3 -> 21.25 | AI3: =R3 -> 0 | AJ3: =S3 -> 0 | AK3: =AD3*AF3/1000 -> 0 | AL3: =AJ3*AD3 -> 0 | AM3: =U3-AL3 -> 0 | AN3: =T3-AK3 -> 0 | AO3: =IF(AN3<>0,Z3*AA3,0) -> 0 | AP3: =AN3/478.332 -> 0 | AQ3: =T3*0.9 -> 0 | AR3: =AK3*0.9 -> 0
A4: =IF(UC_DADOS!$B$2=0,"",UC_DADOS!$B$2) -> #N/A | J4: =IF(H4=0,0,((G4*0.293*I4)/(1000*H4))) -> 0 | K4: 0.7 | L4: =J4*K4 -> 0 | N4: =M4*O4*Q4 -> 0 | Q4: 21.25 | S4: =O4*Q4*R4/765 -> 0 | T4: =N4*L4/1000 -> 0 | U4: =S4*L4 -> 0 | V4: {=IF(F4="A",E4,IFERROR(INDEX('EQUIPAMENTOS_EFICIENTES (BDD)'!G:G,MATCH(1,('EQUIPAMENTOS_EFICIENTES (BDD)'!G:G=E4)*('EQUIPAMENTOS_EFICIENTES (BDD)'!I:I=_xlfn.MINIFS('EQUIPAMENTOS_EFICIENTES (BDD)'!I:I,'EQUIPAMENTOS_EFICIENTES (BDD)'!G:G,E4,'EQUIPAMENTOS_EFICIENTES (BDD)'!I:I,">="&G4)),0)),"Substituição não encontrada"))} -> 0 | W4: {=IF(F4="A",F4,IFERROR(INDEX('EQUIPAMENTOS_EFICIENTES (BDD)'!H:H,MATCH(1,('EQUIPAMENTOS_EFICIENTES (BDD)'!G:G=E4)*('EQUIPAMENTOS_EFICIENTES (BDD)'!I:I=_xlfn.MINIFS('EQUIPAMENTOS_EFICIENTES (BDD)'!I:I,'EQUIPAMENTOS_EFICIENTES (BDD)'!G:G,E4,'EQUIPAMENTOS_EFICIENTES (BDD)'!I:I,">="&G4)),0)),"Substituição não encontrada"))} -> 0 | X4: {=IF(F4="A",G4,IFERROR(INDEX('EQUIPAMENTOS_EFICIENTES (BDD)'!I:I,MATCH(1,('EQUIPAMENTOS_EFICIENTES (BDD)'!G:G=E4)*('EQUIPAMENTOS_EFICIENTES (BDD)'!I:I=_xlfn.MINIFS('EQUIPAMENTOS_EFICIENTES (BDD)'!I:I,'EQUIPAMENTOS_EFICIENTES (BDD)'!G:G,E4,'EQUIPAMENTOS_EFICIENTES (BDD)'!I:I,">="&G4)),0)),"Substituição não encontrada"))} -> 0 | Y4: {=IF(F4="A",H4,IFERROR(INDEX('EQUIPAMENTOS_EFICIENTES (BDD)'!J:J,MATCH(1,('EQUIPAMENTOS_EFICIENTES (BDD)'!G:G=E4)*('EQUIPAMENTOS_EFICIENTES (BDD)'!I:I=_xlfn.MINIFS('EQUIPAMENTOS_EFICIENTES (BDD)'!I:I,'EQUIPAMENTOS_EFICIENTES (BDD)'!G:G,E4,'EQUIPAMENTOS_EFICIENTES (BDD)'!I:I,">="&G4)),0)),"Substituição não encontrada"))} -> 0 | Z4: {=IFERROR(INDEX('EQUIPAMENTOS_EFICIENTES (BDD)'!K:K,MATCH(1,('EQUIPAMENTOS_EFICIENTES (BDD)'!G:G=E4)*('EQUIPAMENTOS_EFICIENTES (BDD)'!I:I=_xlfn.MINIFS('EQUIPAMENTOS_EFICIENTES (BDD)'!I:I,'EQUIPAMENTOS_EFICIENTES (BDD)'!G:G,E4,'EQUIPAMENTOS_EFICIENTES (BDD)'!I:I,">="&G4)),0)),"")} -> 0 | AA4: =I4 -> 0 | AB4: =IF(Y4=0,0,((X4*0.293*AA4)/(1000*Y4))) -> 0 | AC4: =K4 -> 0.7 | AD4: =AB4*AC4 -> 0 | AE4: =M4 -> 0 | AF4: =N4 -> 0 | AG4: =O4 -> 0 | AH4: =Q4 -> 21.25 | AI4: =R4 -> 0 | AJ4: =S4 -> 0 | AK4: =AD4*AF4/1000 -> 0 | AL4: =AJ4*AD4 -> 0 | AM4: =U4-AL4 -> 0 | AN4: =T4-AK4 -> 0 | AO4: =IF(AN4<>0,Z4*AA4,0) -> 0 | AP4: =AN4/478.332 -> 0 | AQ4: =T4*0.9 -> 0 | AR4: =AK4*0.9 -> 0
A5: =IF(UC_DADOS!$B$2=0,"",UC_DADOS!$B$2) -> #N/A | J5: =IF(H5=0,0,((G5*0.293*I5)/(1000*H5))) -> 0 | K5: 0.7 | L5: =J5*K5 -> 0 | N5: =M5*O5*Q5 -> 0 | Q5: 21.25 | S5: =O5*Q5*R5/765 -> 0 | T5: =N5*L5/1000 -> 0 | U5: =S5*L5 -> 0 | V5: {=IF(F5="A",E5,IFERROR(INDEX('EQUIPAMENTOS_EFICIENTES (BDD)'!G:G,MATCH(1,('EQUIPAMENTOS_EFICIENTES (BDD)'!G:G=E5)*('EQUIPAMENTOS_EFICIENTES (BDD)'!I:I=_xlfn.MINIFS('EQUIPAMENTOS_EFICIENTES (BDD)'!I:I,'EQUIPAMENTOS_EFICIENTES (BDD)'!G:G,E5,'EQUIPAMENTOS_EFICIENTES (BDD)'!I:I,">="&G5)),0)),"Substituição não encontrada"))} -> 0 | W5: {=IF(F5="A",F5,IFERROR(INDEX('EQUIPAMENTOS_EFICIENTES (BDD)'!H:H,MATCH(1,('EQUIPAMENTOS_EFICIENTES (BDD)'!G:G=E5)*('EQUIPAMENTOS_EFICIENTES (BDD)'!I:I=_xlfn.MINIFS('EQUIPAMENTOS_EFICIENTES (BDD)'!I:I,'EQUIPAMENTOS_EFICIENTES (BDD)'!G:G,E5,'EQUIPAMENTOS_EFICIENTES (BDD)'!I:I,">="&G5)),0)),"Substituição não encontrada"))} -> 0 | X5: {=IF(F5="A",G5,IFERROR(INDEX('EQUIPAMENTOS_EFICIENTES (BDD)'!I:I,MATCH(1,('EQUIPAMENTOS_EFICIENTES (BDD)'!G:G=E5)*('EQUIPAMENTOS_EFICIENTES (BDD)'!I:I=_xlfn.MINIFS('EQUIPAMENTOS_EFICIENTES (BDD)'!I:I,'EQUIPAMENTOS_EFICIENTES (BDD)'!G:G,E5,'EQUIPAMENTOS_EFICIENTES (BDD)'!I:I,">="&G5)),0)),"Substituição não encontrada"))} -> 0 | Y5: {=IF(F5="A",H5,IFERROR(INDEX('EQUIPAMENTOS_EFICIENTES (BDD)'!J:J,MATCH(1,('EQUIPAMENTOS_EFICIENTES (BDD)'!G:G=E5)*('EQUIPAMENTOS_EFICIENTES (BDD)'!I:I=_xlfn.MINIFS('EQUIPAMENTOS_EFICIENTES (BDD)'!I:I,'EQUIPAMENTOS_EFICIENTES (BDD)'!G:G,E5,'EQUIPAMENTOS_EFICIENTES (BDD)'!I:I,">="&G5)),0)),"Substituição não encontrada"))} -> 0 | Z5: {=IFERROR(INDEX('EQUIPAMENTOS_EFICIENTES (BDD)'!K:K,MATCH(1,('EQUIPAMENTOS_EFICIENTES (BDD)'!G:G=E5)*('EQUIPAMENTOS_EFICIENTES (BDD)'!I:I=_xlfn.MINIFS('EQUIPAMENTOS_EFICIENTES (BDD)'!I:I,'EQUIPAMENTOS_EFICIENTES (BDD)'!G:G,E5,'EQUIPAMENTOS_EFICIENTES (BDD)'!I:I,">="&G5)),0)),"")} -> 0 | AA5: =I5 -> 0 | AB5: =IF(Y5=0,0,((X5*0.293*AA5)/(1000*Y5))) -> 0 | AC5: =K5 -> 0.7 | AD5: =AB5*AC5 -> 0 | AE5: =M5 -> 0 | AF5: =N5 -> 0 | AG5: =O5 -> 0 | AH5: =Q5 -> 21.25 | AI5: =R5 -> 0 | AJ5: =S5 -> 0 | AK5: =AD5*AF5/1000 -> 0 | AL5: =AJ5*AD5 -> 0 | AM5: =U5-AL5 -> 0 | AN5: =T5-AK5 -> 0 | AO5: =IF(AN5<>0,Z5*AA5,0) -> 0 | AP5: =AN5/478.332 -> 0 | AQ5: =T5*0.9 -> 0 | AR5: =AK5*0.9 -> 0
A6: =IF(UC_DADOS!$B$2=0,"",UC_DADOS!$B$2) -> #N/A | J6: =IF(H6=0,0,((G6*0.293*I6)/(1000*H6))) -> 0 | K6: 0.7 | L6: =J6*K6 -> 0 | N6: =M6*O6*Q6 -> 0 | Q6: 21.25 | S6: =O6*Q6*R6/765 -> 0 | T6: =N6*L6/1000 -> 0 | U6: =S6*L6 -> 0 | V6: {=IF(F6="A",E6,IFERROR(INDEX('EQUIPAMENTOS_EFICIENTES (BDD)'!G:G,MATCH(1,('EQUIPAMENTOS_EFICIENTES (BDD)'!G:G=E6)*('EQUIPAMENTOS_EFICIENTES (BDD)'!I:I=_xlfn.MINIFS('EQUIPAMENTOS_EFICIENTES (BDD)'!I:I,'EQUIPAMENTOS_EFICIENTES (BDD)'!G:G,E6,'EQUIPAMENTOS_EFICIENTES (BDD)'!I:I,">="&G6)),0)),"Substituição não encontrada"))} -> 0 | W6: {=IF(F6="A",F6,IFERROR(INDEX('EQUIPAMENTOS_EFICIENTES (BDD)'!H:H,MATCH(1,('EQUIPAMENTOS_EFICIENTES (BDD)'!G:G=E6)*('EQUIPAMENTOS_EFICIENTES (BDD)'!I:I=_xlfn.MINIFS('EQUIPAMENTOS_EFICIENTES (BDD)'!I:I,'EQUIPAMENTOS_EFICIENTES (BDD)'!G:G,E6,'EQUIPAMENTOS_EFICIENTES (BDD)'!I:I,">="&G6)),0)),"Substituição não encontrada"))} -> 0 | X6: {=IF(F6="A",G6,IFERROR(INDEX('EQUIPAMENTOS_EFICIENTES (BDD)'!I:I,MATCH(1,('EQUIPAMENTOS_EFICIENTES (BDD)'!G:G=E6)*('EQUIPAMENTOS_EFICIENTES (BDD)'!I:I=_xlfn.MINIFS('EQUIPAMENTOS_EFICIENTES (BDD)'!I:I,'EQUIPAMENTOS_EFICIENTES (BDD)'!G:G,E6,'EQUIPAMENTOS_EFICIENTES (BDD)'!I:I,">="&G6)),0)),"Substituição não encontrada"))} -> 0 | Y6: {=IF(F6="A",H6,IFERROR(INDEX('EQUIPAMENTOS_EFICIENTES (BDD)'!J:J,MATCH(1,('EQUIPAMENTOS_EFICIENTES (BDD)'!G:G=E6)*('EQUIPAMENTOS_EFICIENTES (BDD)'!I:I=_xlfn.MINIFS('EQUIPAMENTOS_EFICIENTES (BDD)'!I:I,'EQUIPAMENTOS_EFICIENTES (BDD)'!G:G,E6,'EQUIPAMENTOS_EFICIENTES (BDD)'!I:I,">="&G6)),0)),"Substituição não encontrada"))} -> 0 | Z6: {=IFERROR(INDEX('EQUIPAMENTOS_EFICIENTES (BDD)'!K:K,MATCH(1,('EQUIPAMENTOS_EFICIENTES (BDD)'!G:G=E6)*('EQUIPAMENTOS_EFICIENTES (BDD)'!I:I=_xlfn.MINIFS('EQUIPAMENTOS_EFICIENTES (BDD)'!I:I,'EQUIPAMENTOS_EFICIENTES (BDD)'!G:G,E6,'EQUIPAMENTOS_EFICIENTES (BDD)'!I:I,">="&G6)),0)),"")} -> 0 | AA6: =I6 -> 0 | AB6: =IF(Y6=0,0,((X6*0.293*AA6)/(1000*Y6))) -> 0 | AC6: =K6 -> 0.7 | AD6: =AB6*AC6 -> 0 | AE6: =M6 -> 0 | AF6: =N6 -> 0 | AG6: =O6 -> 0 | AH6: =Q6 -> 21.25 | AI6: =R6 -> 0 | AJ6: =S6 -> 0 | AK6: =AD6*AF6/1000 -> 0 | AL6: =AJ6*AD6 -> 0 | AM6: =U6-AL6 -> 0 | AN6: =T6-AK6 -> 0 | AO6: =IF(AN6<>0,Z6*AA6,0) -> 0 | AP6: =AN6/478.332 -> 0 | AQ6: =T6*0.9 -> 0 | AR6: =AK6*0.9 -> 0
A7: =IF(UC_DADOS!$B$2=0,"",UC_DADOS!$B$2) -> #N/A | J7: =IF(H7=0,0,((G7*0.293*I7)/(1000*H7))) -> 0 | K7: 0.7 | L7: =J7*K7 -> 0 | N7: =M7*O7*Q7 -> 0 | Q7: 21.25 | S7: =O7*Q7*R7/765 -> 0 | T7: =N7*L7/1000 -> 0 | U7: =S7*L7 -> 0 | V7: {=IF(F7="A",E7,IFERROR(INDEX('EQUIPAMENTOS_EFICIENTES (BDD)'!G:G,MATCH(1,('EQUIPAMENTOS_EFICIENTES (BDD)'!G:G=E7)*('EQUIPAMENTOS_EFICIENTES (BDD)'!I:I=_xlfn.MINIFS('EQUIPAMENTOS_EFICIENTES (BDD)'!I:I,'EQUIPAMENTOS_EFICIENTES (BDD)'!G:G,E7,'EQUIPAMENTOS_EFICIENTES (BDD)'!I:I,">="&G7)),0)),"Substituição não encontrada"))} -> 0 | W7: {=IF(F7="A",F7,IFERROR(INDEX('EQUIPAMENTOS_EFICIENTES (BDD)'!H:H,MATCH(1,('EQUIPAMENTOS_EFICIENTES (BDD)'!G:G=E7)*('EQUIPAMENTOS_EFICIENTES (BDD)'!I:I=_xlfn.MINIFS('EQUIPAMENTOS_EFICIENTES (BDD)'!I:I,'EQUIPAMENTOS_EFICIENTES (BDD)'!G:G,E7,'EQUIPAMENTOS_EFICIENTES (BDD)'!I:I,">="&G7)),0)),"Substituição não encontrada"))} -> 0 | X7: {=IF(F7="A",G7,IFERROR(INDEX('EQUIPAMENTOS_EFICIENTES (BDD)'!I:I,MATCH(1,('EQUIPAMENTOS_EFICIENTES (BDD)'!G:G=E7)*('EQUIPAMENTOS_EFICIENTES (BDD)'!I:I=_xlfn.MINIFS('EQUIPAMENTOS_EFICIENTES (BDD)'!I:I,'EQUIPAMENTOS_EFICIENTES (BDD)'!G:G,E7,'EQUIPAMENTOS_EFICIENTES (BDD)'!I:I,">="&G7)),0)),"Substituição não encontrada"))} -> 0 | Y7: {=IF(F7="A",H7,IFERROR(INDEX('EQUIPAMENTOS_EFICIENTES (BDD)'!J:J,MATCH(1,('EQUIPAMENTOS_EFICIENTES (BDD)'!G:G=E7)*('EQUIPAMENTOS_EFICIENTES (BDD)'!I:I=_xlfn.MINIFS('EQUIPAMENTOS_EFICIENTES (BDD)'!I:I,'EQUIPAMENTOS_EFICIENTES (BDD)'!G:G,E7,'EQUIPAMENTOS_EFICIENTES (BDD)'!I:I,">="&G7)),0)),"Substituição não encontrada"))} -> 0 | Z7: {=IFERROR(INDEX('EQUIPAMENTOS_EFICIENTES (BDD)'!K:K,MATCH(1,('EQUIPAMENTOS_EFICIENTES (BDD)'!G:G=E7)*('EQUIPAMENTOS_EFICIENTES (BDD)'!I:I=_xlfn.MINIFS('EQUIPAMENTOS_EFICIENTES (BDD)'!I:I,'EQUIPAMENTOS_EFICIENTES (BDD)'!G:G,E7,'EQUIPAMENTOS_EFICIENTES (BDD)'!I:I,">="&G7)),0)),"")} -> 0 | AA7: =I7 -> 0 | AB7: =IF(Y7=0,0,((X7*0.293*AA7)/(1000*Y7))) -> 0 | AC7: =K7 -> 0.7 | AD7: =AB7*AC7 -> 0 | AE7: =M7 -> 0 | AF7: =N7 -> 0 | AG7: =O7 -> 0 | AH7: =Q7 -> 21.25 | AI7: =R7 -> 0 | AJ7: =S7 -> 0 | AK7: =AD7*AF7/1000 -> 0 | AL7: =AJ7*AD7 -> 0 | AM7: =U7-AL7 -> 0 | AN7: =T7-AK7 -> 0 | AO7: =IF(AN7<>0,Z7*AA7,0) -> 0 | AP7: =AN7/478.332 -> 0 | AQ7: =T7*0.9 -> 0 | AR7: =AK7*0.9 -> 0
A8: =IF(UC_DADOS!$B$2=0,"",UC_DADOS!$B$2) -> #N/A | J8: =IF(H8=0,0,((G8*0.293*I8)/(1000*H8))) -> 0 | K8: 0.7 | L8: =J8*K8 -> 0 | N8: =M8*O8*Q8 -> 0 | Q8: 21.25 | S8: =O8*Q8*R8/765 -> 0 | T8: =N8*L8/1000 -> 0 | U8: =S8*L8 -> 0 | V8: {=IF(F8="A",E8,IFERROR(INDEX('EQUIPAMENTOS_EFICIENTES (BDD)'!G:G,MATCH(1,('EQUIPAMENTOS_EFICIENTES (BDD)'!G:G=E8)*('EQUIPAMENTOS_EFICIENTES (BDD)'!I:I=_xlfn.MINIFS('EQUIPAMENTOS_EFICIENTES (BDD)'!I:I,'EQUIPAMENTOS_EFICIENTES (BDD)'!G:G,E8,'EQUIPAMENTOS_EFICIENTES (BDD)'!I:I,">="&G8)),0)),"Substituição não encontrada"))} -> 0 | W8: {=IF(F8="A",F8,IFERROR(INDEX('EQUIPAMENTOS_EFICIENTES (BDD)'!H:H,MATCH(1,('EQUIPAMENTOS_EFICIENTES (BDD)'!G:G=E8)*('EQUIPAMENTOS_EFICIENTES (BDD)'!I:I=_xlfn.MINIFS('EQUIPAMENTOS_EFICIENTES (BDD)'!I:I,'EQUIPAMENTOS_EFICIENTES (BDD)'!G:G,E8,'EQUIPAMENTOS_EFICIENTES (BDD)'!I:I,">="&G8)),0)),"Substituição não encontrada"))} -> 0 | X8: {=IF(F8="A",G8,IFERROR(INDEX('EQUIPAMENTOS_EFICIENTES (BDD)'!I:I,MATCH(1,('EQUIPAMENTOS_EFICIENTES (BDD)'!G:G=E8)*('EQUIPAMENTOS_EFICIENTES (BDD)'!I:I=_xlfn.MINIFS('EQUIPAMENTOS_EFICIENTES (BDD)'!I:I,'EQUIPAMENTOS_EFICIENTES (BDD)'!G:G,E8,'EQUIPAMENTOS_EFICIENTES (BDD)'!I:I,">="&G8)),0)),"Substituição não encontrada"))} -> 0 | Y8: {=IF(F8="A",H8,IFERROR(INDEX('EQUIPAMENTOS_EFICIENTES (BDD)'!J:J,MATCH(1,('EQUIPAMENTOS_EFICIENTES (BDD)'!G:G=E8)*('EQUIPAMENTOS_EFICIENTES (BDD)'!I:I=_xlfn.MINIFS('EQUIPAMENTOS_EFICIENTES (BDD)'!I:I,'EQUIPAMENTOS_EFICIENTES (BDD)'!G:G,E8,'EQUIPAMENTOS_EFICIENTES (BDD)'!I:I,">="&G8)),0)),"Substituição não encontrada"))} -> 0 | Z8: {=IFERROR(INDEX('EQUIPAMENTOS_EFICIENTES (BDD)'!K:K,MATCH(1,('EQUIPAMENTOS_EFICIENTES (BDD)'!G:G=E8)*('EQUIPAMENTOS_EFICIENTES (BDD)'!I:I=_xlfn.MINIFS('EQUIPAMENTOS_EFICIENTES (BDD)'!I:I,'EQUIPAMENTOS_EFICIENTES (BDD)'!G:G,E8,'EQUIPAMENTOS_EFICIENTES (BDD)'!I:I,">="&G8)),0)),"")} -> 0 | AA8: =I8 -> 0 | AB8: =IF(Y8=0,0,((X8*0.293*AA8)/(1000*Y8))) -> 0 | AC8: =K8 -> 0.7 | AD8: =AB8*AC8 -> 0 | AE8: =M8 -> 0 | AF8: =N8 -> 0 | AG8: =O8 -> 0 | AH8: =Q8 -> 21.25 | AI8: =R8 -> 0 | AJ8: =S8 -> 0 | AK8: =AD8*AF8/1000 -> 0 | AL8: =AJ8*AD8 -> 0 | AM8: =U8-AL8 -> 0 | AN8: =T8-AK8 -> 0 | AO8: =IF(AN8<>0,Z8*AA8,0) -> 0 | AP8: =AN8/478.332 -> 0 | AQ8: =T8*0.9 -> 0 | AR8: =AK8*0.9 -> 0
A9: =IF(UC_DADOS!$B$2=0,"",UC_DADOS!$B$2) -> #N/A | J9: =IF(H9=0,0,((G9*0.293*I9)/(1000*H9))) -> 0 | K9: 0.7 | L9: =J9*K9 -> 0 | N9: =M9*O9*Q9 -> 0 | Q9: 21.25 | S9: =O9*Q9*R9/765 -> 0 | T9: =N9*L9/1000 -> 0 | U9: =S9*L9 -> 0 | V9: {=IF(F9="A",E9,IFERROR(INDEX('EQUIPAMENTOS_EFICIENTES (BDD)'!G:G,MATCH(1,('EQUIPAMENTOS_EFICIENTES (BDD)'!G:G=E9)*('EQUIPAMENTOS_EFICIENTES (BDD)'!I:I=_xlfn.MINIFS('EQUIPAMENTOS_EFICIENTES (BDD)'!I:I,'EQUIPAMENTOS_EFICIENTES (BDD)'!G:G,E9,'EQUIPAMENTOS_EFICIENTES (BDD)'!I:I,">="&G9)),0)),"Substituição não encontrada"))} -> 0 | W9: {=IF(F9="A",F9,IFERROR(INDEX('EQUIPAMENTOS_EFICIENTES (BDD)'!H:H,MATCH(1,('EQUIPAMENTOS_EFICIENTES (BDD)'!G:G=E9)*('EQUIPAMENTOS_EFICIENTES (BDD)'!I:I=_xlfn.MINIFS('EQUIPAMENTOS_EFICIENTES (BDD)'!I:I,'EQUIPAMENTOS_EFICIENTES (BDD)'!G:G,E9,'EQUIPAMENTOS_EFICIENTES (BDD)'!I:I,">="&G9)),0)),"Substituição não encontrada"))} -> 0 | X9: {=IF(F9="A",G9,IFERROR(INDEX('EQUIPAMENTOS_EFICIENTES (BDD)'!I:I,MATCH(1,('EQUIPAMENTOS_EFICIENTES (BDD)'!G:G=E9)*('EQUIPAMENTOS_EFICIENTES (BDD)'!I:I=_xlfn.MINIFS('EQUIPAMENTOS_EFICIENTES (BDD)'!I:I,'EQUIPAMENTOS_EFICIENTES (BDD)'!G:G,E9,'EQUIPAMENTOS_EFICIENTES (BDD)'!I:I,">="&G9)),0)),"Substituição não encontrada"))} -> 0 | Y9: {=IF(F9="A",H9,IFERROR(INDEX('EQUIPAMENTOS_EFICIENTES (BDD)'!J:J,MATCH(1,('EQUIPAMENTOS_EFICIENTES (BDD)'!G:G=E9)*('EQUIPAMENTOS_EFICIENTES (BDD)'!I:I=_xlfn.MINIFS('EQUIPAMENTOS_EFICIENTES (BDD)'!I:I,'EQUIPAMENTOS_EFICIENTES (BDD)'!G:G,E9,'EQUIPAMENTOS_EFICIENTES (BDD)'!I:I,">="&G9)),0)),"Substituição não encontrada"))} -> 0 | Z9: {=IFERROR(INDEX('EQUIPAMENTOS_EFICIENTES (BDD)'!K:K,MATCH(1,('EQUIPAMENTOS_EFICIENTES (BDD)'!G:G=E9)*('EQUIPAMENTOS_EFICIENTES (BDD)'!I:I=_xlfn.MINIFS('EQUIPAMENTOS_EFICIENTES (BDD)'!I:I,'EQUIPAMENTOS_EFICIENTES (BDD)'!G:G,E9,'EQUIPAMENTOS_EFICIENTES (BDD)'!I:I,">="&G9)),0)),"")} -> 0 | AA9: =I9 -> 0 | AB9: =IF(Y9=0,0,((X9*0.293*AA9)/(1000*Y9))) -> 0 | AC9: =K9 -> 0.7 | AD9: =AB9*AC9 -> 0 | AE9: =M9 -> 0 | AF9: =N9 -> 0 | AG9: =O9 -> 0 | AH9: =Q9 -> 21.25 | AI9: =R9 -> 0 | AJ9: =S9 -> 0 | AK9: =AD9*AF9/1000 -> 0 | AL9: =AJ9*AD9 -> 0 | AM9: =U9-AL9 -> 0 | AN9: =T9-AK9 -> 0 | AO9: =IF(AN9<>0,Z9*AA9,0) -> 0 | AP9: =AN9/478.332 -> 0 | AQ9: =T9*0.9 -> 0 | AR9: =AK9*0.9 -> 0
A10: =IF(UC_DADOS!$B$2=0,"",UC_DADOS!$B$2) -> #N/A | J10: =IF(H10=0,0,((G10*0.293*I10)/(1000*H10))) -> 0 | K10: 0.7 | L10: =J10*K10 -> 0 | N10: =M10*O10*Q10 -> 0 | Q10: 21.25 | S10: =O10*Q10*R10/765 -> 0 | T10: =N10*L10/1000 -> 0 | U10: =S10*L10 -> 0 | V10: {=IF(F10="A",E10,IFERROR(INDEX('EQUIPAMENTOS_EFICIENTES (BDD)'!G:G,MATCH(1,('EQUIPAMENTOS_EFICIENTES (BDD)'!G:G=E10)*('EQUIPAMENTOS_EFICIENTES (BDD)'!I:I=_xlfn.MINIFS('EQUIPAMENTOS_EFICIENTES (BDD)'!I:I,'EQUIPAMENTOS_EFICIENTES (BDD)'!G:G,E10,'EQUIPAMENTOS_EFICIENTES (BDD)'!I:I,">="&G10)),0)),"Substituição não encontrada"))} -> 0 | W10: {=IF(F10="A",F10,IFERROR(INDEX('EQUIPAMENTOS_EFICIENTES (BDD)'!H:H,MATCH(1,('EQUIPAMENTOS_EFICIENTES (BDD)'!G:G=E10)*('EQUIPAMENTOS_EFICIENTES (BDD)'!I:I=_xlfn.MINIFS('EQUIPAMENTOS_EFICIENTES (BDD)'!I:I,'EQUIPAMENTOS_EFICIENTES (BDD)'!G:G,E10,'EQUIPAMENTOS_EFICIENTES (BDD)'!I:I,">="&G10)),0)),"Substituição não encontrada"))} -> 0 | X10: {=IF(F10="A",G10,IFERROR(INDEX('EQUIPAMENTOS_EFICIENTES (BDD)'!I:I,MATCH(1,('EQUIPAMENTOS_EFICIENTES (BDD)'!G:G=E10)*('EQUIPAMENTOS_EFICIENTES (BDD)'!I:I=_xlfn.MINIFS('EQUIPAMENTOS_EFICIENTES (BDD)'!I:I,'EQUIPAMENTOS_EFICIENTES (BDD)'!G:G,E10,'EQUIPAMENTOS_EFICIENTES (BDD)'!I:I,">="&G10)),0)),"Substituição não encontrada"))} -> 0 | Y10: {=IF(F10="A",H10,IFERROR(INDEX('EQUIPAMENTOS_EFICIENTES (BDD)'!J:J,MATCH(1,('EQUIPAMENTOS_EFICIENTES (BDD)'!G:G=E10)*('EQUIPAMENTOS_EFICIENTES (BDD)'!I:I=_xlfn.MINIFS('EQUIPAMENTOS_EFICIENTES (BDD)'!I:I,'EQUIPAMENTOS_EFICIENTES (BDD)'!G:G,E10,'EQUIPAMENTOS_EFICIENTES (BDD)'!I:I,">="&G10)),0)),"Substituição não encontrada"))} -> 0 | Z10: {=IFERROR(INDEX('EQUIPAMENTOS_EFICIENTES (BDD)'!K:K,MATCH(1,('EQUIPAMENTOS_EFICIENTES (BDD)'!G:G=E10)*('EQUIPAMENTOS_EFICIENTES (BDD)'!I:I=_xlfn.MINIFS('EQUIPAMENTOS_EFICIENTES (BDD)'!I:I,'EQUIPAMENTOS_EFICIENTES (BDD)'!G:G,E10,'EQUIPAMENTOS_EFICIENTES (BDD)'!I:I,">="&G10)),0)),"")} -> 0 | AA10: =I10 -> 0 | AB10: =IF(Y10=0,0,((X10*0.293*AA10)/(1000*Y10))) -> 0 | AC10: =K10 -> 0.7 | AD10: =AB10*AC10 -> 0 | AE10: =M10 -> 0 | AF10: =N10 -> 0 | AG10: =O10 -> 0 | AH10: =Q10 -> 21.25 | AI10: =R10 -> 0 | AJ10: =S10 -> 0 | AK10: =AD10*AF10/1000 -> 0 | AL10: =AJ10*AD10 -> 0 | AM10: =U10-AL10 -> 0 | AN10: =T10-AK10 -> 0 | AO10: =IF(AN10<>0,Z10*AA10,0) -> 0 | AP10: =AN10/478.332 -> 0 | AQ10: =T10*0.9 -> 0 | AR10: =AK10*0.9 -> 0
A11: =IF(UC_DADOS!$B$2=0,"",UC_DADOS!$B$2) -> #N/A | J11: =IF(H11=0,0,((G11*0.293*I11)/(1000*H11))) -> 0 | K11: 0.7 | L11: =J11*K11 -> 0 | N11: =M11*O11*Q11 -> 0 | Q11: 21.25 | S11: =O11*Q11*R11/765 -> 0 | T11: =N11*L11/1000 -> 0 | U11: =S11*L11 -> 0 | V11: {=IF(F11="A",E11,IFERROR(INDEX('EQUIPAMENTOS_EFICIENTES (BDD)'!G:G,MATCH(1,('EQUIPAMENTOS_EFICIENTES (BDD)'!G:G=E11)*('EQUIPAMENTOS_EFICIENTES (BDD)'!I:I=_xlfn.MINIFS('EQUIPAMENTOS_EFICIENTES (BDD)'!I:I,'EQUIPAMENTOS_EFICIENTES (BDD)'!G:G,E11,'EQUIPAMENTOS_EFICIENTES (BDD)'!I:I,">="&G11)),0)),"Substituição não encontrada"))} -> 0 | W11: {=IF(F11="A",F11,IFERROR(INDEX('EQUIPAMENTOS_EFICIENTES (BDD)'!H:H,MATCH(1,('EQUIPAMENTOS_EFICIENTES (BDD)'!G:G=E11)*('EQUIPAMENTOS_EFICIENTES (BDD)'!I:I=_xlfn.MINIFS('EQUIPAMENTOS_EFICIENTES (BDD)'!I:I,'EQUIPAMENTOS_EFICIENTES (BDD)'!G:G,E11,'EQUIPAMENTOS_EFICIENTES (BDD)'!I:I,">="&G11)),0)),"Substituição não encontrada"))} -> 0 | X11: {=IF(F11="A",G11,IFERROR(INDEX('EQUIPAMENTOS_EFICIENTES (BDD)'!I:I,MATCH(1,('EQUIPAMENTOS_EFICIENTES (BDD)'!G:G=E11)*('EQUIPAMENTOS_EFICIENTES (BDD)'!I:I=_xlfn.MINIFS('EQUIPAMENTOS_EFICIENTES (BDD)'!I:I,'EQUIPAMENTOS_EFICIENTES (BDD)'!G:G,E11,'EQUIPAMENTOS_EFICIENTES (BDD)'!I:I,">="&G11)),0)),"Substituição não encontrada"))} -> 0 | Y11: {=IF(F11="A",H11,IFERROR(INDEX('EQUIPAMENTOS_EFICIENTES (BDD)'!J:J,MATCH(1,('EQUIPAMENTOS_EFICIENTES (BDD)'!G:G=E11)*('EQUIPAMENTOS_EFICIENTES (BDD)'!I:I=_xlfn.MINIFS('EQUIPAMENTOS_EFICIENTES (BDD)'!I:I,'EQUIPAMENTOS_EFICIENTES (BDD)'!G:G,E11,'EQUIPAMENTOS_EFICIENTES (BDD)'!I:I,">="&G11)),0)),"Substituição não encontrada"))} -> 0 | Z11: {=IFERROR(INDEX('EQUIPAMENTOS_EFICIENTES (BDD)'!K:K,MATCH(1,('EQUIPAMENTOS_EFICIENTES (BDD)'!G:G=E11)*('EQUIPAMENTOS_EFICIENTES (BDD)'!I:I=_xlfn.MINIFS('EQUIPAMENTOS_EFICIENTES (BDD)'!I:I,'EQUIPAMENTOS_EFICIENTES (BDD)'!G:G,E11,'EQUIPAMENTOS_EFICIENTES (BDD)'!I:I,">="&G11)),0)),"")} -> 0 | AA11: =I11 -> 0 | AB11: =IF(Y11=0,0,((X11*0.293*AA11)/(1000*Y11))) -> 0 | AC11: =K11 -> 0.7 | AD11: =AB11*AC11 -> 0 | AE11: =M11 -> 0 | AF11: =N11 -> 0 | AG11: =O11 -> 0 | AH11: =Q11 -> 21.25 | AI11: =R11 -> 0 | AJ11: =S11 -> 0 | AK11: =AD11*AF11/1000 -> 0 | AL11: =AJ11*AD11 -> 0 | AM11: =U11-AL11 -> 0 | AN11: =T11-AK11 -> 0 | AO11: =IF(AN11<>0,Z11*AA11,0) -> 0 | AP11: =AN11/478.332 -> 0 | AQ11: =T11*0.9 -> 0 | AR11: =AK11*0.9 -> 0
A12: =IF(UC_DADOS!$B$2=0,"",UC_DADOS!$B$2) -> #N/A | J12: =IF(H12=0,0,((G12*0.293*I12)/(1000*H12))) -> 0 | K12: 0.7 | L12: =J12*K12 -> 0 | N12: =M12*O12*Q12 -> 0 | Q12: 21.25 | S12: =O12*Q12*R12/765 -> 0 | T12: =N12*L12/1000 -> 0 | U12: =S12*L12 -> 0 | V12: {=IF(F12="A",E12,IFERROR(INDEX('EQUIPAMENTOS_EFICIENTES (BDD)'!G:G,MATCH(1,('EQUIPAMENTOS_EFICIENTES (BDD)'!G:G=E12)*('EQUIPAMENTOS_EFICIENTES (BDD)'!I:I=_xlfn.MINIFS('EQUIPAMENTOS_EFICIENTES (BDD)'!I:I,'EQUIPAMENTOS_EFICIENTES (BDD)'!G:G,E12,'EQUIPAMENTOS_EFICIENTES (BDD)'!I:I,">="&G12)),0)),"Substituição não encontrada"))} -> 0 | W12: {=IF(F12="A",F12,IFERROR(INDEX('EQUIPAMENTOS_EFICIENTES (BDD)'!H:H,MATCH(1,('EQUIPAMENTOS_EFICIENTES (BDD)'!G:G=E12)*('EQUIPAMENTOS_EFICIENTES (BDD)'!I:I=_xlfn.MINIFS('EQUIPAMENTOS_EFICIENTES (BDD)'!I:I,'EQUIPAMENTOS_EFICIENTES (BDD)'!G:G,E12,'EQUIPAMENTOS_EFICIENTES (BDD)'!I:I,">="&G12)),0)),"Substituição não encontrada"))} -> 0 | X12: {=IF(F12="A",G12,IFERROR(INDEX('EQUIPAMENTOS_EFICIENTES (BDD)'!I:I,MATCH(1,('EQUIPAMENTOS_EFICIENTES (BDD)'!G:G=E12)*('EQUIPAMENTOS_EFICIENTES (BDD)'!I:I=_xlfn.MINIFS('EQUIPAMENTOS_EFICIENTES (BDD)'!I:I,'EQUIPAMENTOS_EFICIENTES (BDD)'!G:G,E12,'EQUIPAMENTOS_EFICIENTES (BDD)'!I:I,">="&G12)),0)),"Substituição não encontrada"))} -> 0 | Y12: {=IF(F12="A",H12,IFERROR(INDEX('EQUIPAMENTOS_EFICIENTES (BDD)'!J:J,MATCH(1,('EQUIPAMENTOS_EFICIENTES (BDD)'!G:G=E12)*('EQUIPAMENTOS_EFICIENTES (BDD)'!I:I=_xlfn.MINIFS('EQUIPAMENTOS_EFICIENTES (BDD)'!I:I,'EQUIPAMENTOS_EFICIENTES (BDD)'!G:G,E12,'EQUIPAMENTOS_EFICIENTES (BDD)'!I:I,">="&G12)),0)),"Substituição não encontrada"))} -> 0 | Z12: {=IFERROR(INDEX('EQUIPAMENTOS_EFICIENTES (BDD)'!K:K,MATCH(1,('EQUIPAMENTOS_EFICIENTES (BDD)'!G:G=E12)*('EQUIPAMENTOS_EFICIENTES (BDD)'!I:I=_xlfn.MINIFS('EQUIPAMENTOS_EFICIENTES (BDD)'!I:I,'EQUIPAMENTOS_EFICIENTES (BDD)'!G:G,E12,'EQUIPAMENTOS_EFICIENTES (BDD)'!I:I,">="&G12)),0)),"")} -> 0 | AA12: =I12 -> 0 | AB12: =IF(Y12=0,0,((X12*0.293*AA12)/(1000*Y12))) -> 0 | AC12: =K12 -> 0.7 | AD12: =AB12*AC12 -> 0 | AE12: =M12 -> 0 | AF12: =N12 -> 0 | AG12: =O12 -> 0 | AH12: =Q12 -> 21.25 | AI12: =R12 -> 0 | AJ12: =S12 -> 0 | AK12: =AD12*AF12/1000 -> 0 | AL12: =AJ12*AD12 -> 0 | AM12: =U12-AL12 -> 0 | AN12: =T12-AK12 -> 0 | AO12: =IF(AN12<>0,Z12*AA12,0) -> 0 | AP12: =AN12/478.332 -> 0 | AQ12: =T12*0.9 -> 0 | AR12: =AK12*0.9 -> 0
A13: =IF(UC_DADOS!$B$2=0,"",UC_DADOS!$B$2) -> #N/A | J13: =IF(H13=0,0,((G13*0.293*I13)/(1000*H13))) -> 0 | K13: 0.7 | L13: =J13*K13 -> 0 | N13: =M13*O13*Q13 -> 0 | Q13: 21.25 | S13: =O13*Q13*R13/765 -> 0 | T13: =N13*L13/1000 -> 0 | U13: =S13*L13 -> 0 | V13: {=IF(F13="A",E13,IFERROR(INDEX('EQUIPAMENTOS_EFICIENTES (BDD)'!G:G,MATCH(1,('EQUIPAMENTOS_EFICIENTES (BDD)'!G:G=E13)*('EQUIPAMENTOS_EFICIENTES (BDD)'!I:I=_xlfn.MINIFS('EQUIPAMENTOS_EFICIENTES (BDD)'!I:I,'EQUIPAMENTOS_EFICIENTES (BDD)'!G:G,E13,'EQUIPAMENTOS_EFICIENTES (BDD)'!I:I,">="&G13)),0)),"Substituição não encontrada"))} -> 0 | W13: {=IF(F13="A",F13,IFERROR(INDEX('EQUIPAMENTOS_EFICIENTES (BDD)'!H:H,MATCH(1,('EQUIPAMENTOS_EFICIENTES (BDD)'!G:G=E13)*('EQUIPAMENTOS_EFICIENTES (BDD)'!I:I=_xlfn.MINIFS('EQUIPAMENTOS_EFICIENTES (BDD)'!I:I,'EQUIPAMENTOS_EFICIENTES (BDD)'!G:G,E13,'EQUIPAMENTOS_EFICIENTES (BDD)'!I:I,">="&G13)),0)),"Substituição não encontrada"))} -> 0 | X13: {=IF(F13="A",G13,IFERROR(INDEX('EQUIPAMENTOS_EFICIENTES (BDD)'!I:I,MATCH(1,('EQUIPAMENTOS_EFICIENTES (BDD)'!G:G=E13)*('EQUIPAMENTOS_EFICIENTES (BDD)'!I:I=_xlfn.MINIFS('EQUIPAMENTOS_EFICIENTES (BDD)'!I:I,'EQUIPAMENTOS_EFICIENTES (BDD)'!G:G,E13,'EQUIPAMENTOS_EFICIENTES (BDD)'!I:I,">="&G13)),0)),"Substituição não encontrada"))} -> 0 | Y13: {=IF(F13="A",H13,IFERROR(INDEX('EQUIPAMENTOS_EFICIENTES (BDD)'!J:J,MATCH(1,('EQUIPAMENTOS_EFICIENTES (BDD)'!G:G=E13)*('EQUIPAMENTOS_EFICIENTES (BDD)'!I:I=_xlfn.MINIFS('EQUIPAMENTOS_EFICIENTES (BDD)'!I:I,'EQUIPAMENTOS_EFICIENTES (BDD)'!G:G,E13,'EQUIPAMENTOS_EFICIENTES (BDD)'!I:I,">="&G13)),0)),"Substituição não encontrada"))} -> 0 | Z13: {=IFERROR(INDEX('EQUIPAMENTOS_EFICIENTES (BDD)'!K:K,MATCH(1,('EQUIPAMENTOS_EFICIENTES (BDD)'!G:G=E13)*('EQUIPAMENTOS_EFICIENTES (BDD)'!I:I=_xlfn.MINIFS('EQUIPAMENTOS_EFICIENTES (BDD)'!I:I,'EQUIPAMENTOS_EFICIENTES (BDD)'!G:G,E13,'EQUIPAMENTOS_EFICIENTES (BDD)'!I:I,">="&G13)),0)),"")} -> 0 | AA13: =I13 -> 0 | AB13: =IF(Y13=0,0,((X13*0.293*AA13)/(1000*Y13))) -> 0 | AC13: =K13 -> 0.7 | AD13: =AB13*AC13 -> 0 | AE13: =M13 -> 0 | AF13: =N13 -> 0 | AG13: =O13 -> 0 | AH13: =Q13 -> 21.25 | AI13: =R13 -> 0 | AJ13: =S13 -> 0 | AK13: =AD13*AF13/1000 -> 0 | AL13: =AJ13*AD13 -> 0 | AM13: =U13-AL13 -> 0 | AN13: =T13-AK13 -> 0 | AO13: =IF(AN13<>0,Z13*AA13,0) -> 0 | AP13: =AN13/478.332 -> 0 | AQ13: =T13*0.9 -> 0 | AR13: =AK13*0.9 -> 0
A14: =IF(UC_DADOS!$B$2=0,"",UC_DADOS!$B$2) -> #N/A | J14: =IF(H14=0,0,((G14*0.293*I14)/(1000*H14))) -> 0 | K14: 0.7 | L14: =J14*K14 -> 0 | N14: =M14*O14*Q14 -> 0 | Q14: 21.25 | S14: =O14*Q14*R14/765 -> 0 | T14: =N14*L14/1000 -> 0 | U14: =S14*L14 -> 0 | V14: {=IF(F14="A",E14,IFERROR(INDEX('EQUIPAMENTOS_EFICIENTES (BDD)'!G:G,MATCH(1,('EQUIPAMENTOS_EFICIENTES (BDD)'!G:G=E14)*('EQUIPAMENTOS_EFICIENTES (BDD)'!I:I=_xlfn.MINIFS('EQUIPAMENTOS_EFICIENTES (BDD)'!I:I,'EQUIPAMENTOS_EFICIENTES (BDD)'!G:G,E14,'EQUIPAMENTOS_EFICIENTES (BDD)'!I:I,">="&G14)),0)),"Substituição não encontrada"))} -> 0 | W14: {=IF(F14="A",F14,IFERROR(INDEX('EQUIPAMENTOS_EFICIENTES (BDD)'!H:H,MATCH(1,('EQUIPAMENTOS_EFICIENTES (BDD)'!G:G=E14)*('EQUIPAMENTOS_EFICIENTES (BDD)'!I:I=_xlfn.MINIFS('EQUIPAMENTOS_EFICIENTES (BDD)'!I:I,'EQUIPAMENTOS_EFICIENTES (BDD)'!G:G,E14,'EQUIPAMENTOS_EFICIENTES (BDD)'!I:I,">="&G14)),0)),"Substituição não encontrada"))} -> 0 | X14: {=IF(F14="A",G14,IFERROR(INDEX('EQUIPAMENTOS_EFICIENTES (BDD)'!I:I,MATCH(1,('EQUIPAMENTOS_EFICIENTES (BDD)'!G:G=E14)*('EQUIPAMENTOS_EFICIENTES (BDD)'!I:I=_xlfn.MINIFS('EQUIPAMENTOS_EFICIENTES (BDD)'!I:I,'EQUIPAMENTOS_EFICIENTES (BDD)'!G:G,E14,'EQUIPAMENTOS_EFICIENTES (BDD)'!I:I,">="&G14)),0)),"Substituição não encontrada"))} -> 0 | Y14: {=IF(F14="A",H14,IFERROR(INDEX('EQUIPAMENTOS_EFICIENTES (BDD)'!J:J,MATCH(1,('EQUIPAMENTOS_EFICIENTES (BDD)'!G:G=E14)*('EQUIPAMENTOS_EFICIENTES (BDD)'!I:I=_xlfn.MINIFS('EQUIPAMENTOS_EFICIENTES (BDD)'!I:I,'EQUIPAMENTOS_EFICIENTES (BDD)'!G:G,E14,'EQUIPAMENTOS_EFICIENTES (BDD)'!I:I,">="&G14)),0)),"Substituição não encontrada"))} -> 0 | Z14: {=IFERROR(INDEX('EQUIPAMENTOS_EFICIENTES (BDD)'!K:K,MATCH(1,('EQUIPAMENTOS_EFICIENTES (BDD)'!G:G=E14)*('EQUIPAMENTOS_EFICIENTES (BDD)'!I:I=_xlfn.MINIFS('EQUIPAMENTOS_EFICIENTES (BDD)'!I:I,'EQUIPAMENTOS_EFICIENTES (BDD)'!G:G,E14,'EQUIPAMENTOS_EFICIENTES (BDD)'!I:I,">="&G14)),0)),"")} -> 0 | AA14: =I14 -> 0 | AB14: =IF(Y14=0,0,((X14*0.293*AA14)/(1000*Y14))) -> 0 | AC14: =K14 -> 0.7 | AD14: =AB14*AC14 -> 0 | AE14: =M14 -> 0 | AF14: =N14 -> 0 | AG14: =O14 -> 0 | AH14: =Q14 -> 21.25 | AI14: =R14 -> 0 | AJ14: =S14 -> 0 | AK14: =AD14*AF14/1000 -> 0 | AL14: =AJ14*AD14 -> 0 | AM14: =U14-AL14 -> 0 | AN14: =T14-AK14 -> 0 | AO14: =IF(AN14<>0,Z14*AA14,0) -> 0 | AP14: =AN14/478.332 -> 0 | AQ14: =T14*0.9 -> 0 | AR14: =AK14*0.9 -> 0
A15: =IF(UC_DADOS!$B$2=0,"",UC_DADOS!$B$2) -> #N/A | J15: =IF(H15=0,0,((G15*0.293*I15)/(1000*H15))) -> 0 | K15: 0.7 | L15: =J15*K15 -> 0 | N15: =M15*O15*Q15 -> 0 | Q15: 21.25 | S15: =O15*Q15*R15/765 -> 0 | T15: =N15*L15/1000 -> 0 | U15: =S15*L15 -> 0 | V15: {=IF(F15="A",E15,IFERROR(INDEX('EQUIPAMENTOS_EFICIENTES (BDD)'!G:G,MATCH(1,('EQUIPAMENTOS_EFICIENTES (BDD)'!G:G=E15)*('EQUIPAMENTOS_EFICIENTES (BDD)'!I:I=_xlfn.MINIFS('EQUIPAMENTOS_EFICIENTES (BDD)'!I:I,'EQUIPAMENTOS_EFICIENTES (BDD)'!G:G,E15,'EQUIPAMENTOS_EFICIENTES (BDD)'!I:I,">="&G15)),0)),"Substituição não encontrada"))} -> 0 | W15: {=IF(F15="A",F15,IFERROR(INDEX('EQUIPAMENTOS_EFICIENTES (BDD)'!H:H,MATCH(1,('EQUIPAMENTOS_EFICIENTES (BDD)'!G:G=E15)*('EQUIPAMENTOS_EFICIENTES (BDD)'!I:I=_xlfn.MINIFS('EQUIPAMENTOS_EFICIENTES (BDD)'!I:I,'EQUIPAMENTOS_EFICIENTES (BDD)'!G:G,E15,'EQUIPAMENTOS_EFICIENTES (BDD)'!I:I,">="&G15)),0)),"Substituição não encontrada"))} -> 0 | X15: {=IF(F15="A",G15,IFERROR(INDEX('EQUIPAMENTOS_EFICIENTES (BDD)'!I:I,MATCH(1,('EQUIPAMENTOS_EFICIENTES (BDD)'!G:G=E15)*('EQUIPAMENTOS_EFICIENTES (BDD)'!I:I=_xlfn.MINIFS('EQUIPAMENTOS_EFICIENTES (BDD)'!I:I,'EQUIPAMENTOS_EFICIENTES (BDD)'!G:G,E15,'EQUIPAMENTOS_EFICIENTES (BDD)'!I:I,">="&G15)),0)),"Substituição não encontrada"))} -> 0 | Y15: {=IF(F15="A",H15,IFERROR(INDEX('EQUIPAMENTOS_EFICIENTES (BDD)'!J:J,MATCH(1,('EQUIPAMENTOS_EFICIENTES (BDD)'!G:G=E15)*('EQUIPAMENTOS_EFICIENTES (BDD)'!I:I=_xlfn.MINIFS('EQUIPAMENTOS_EFICIENTES (BDD)'!I:I,'EQUIPAMENTOS_EFICIENTES (BDD)'!G:G,E15,'EQUIPAMENTOS_EFICIENTES (BDD)'!I:I,">="&G15)),0)),"Substituição não encontrada"))} -> 0 | Z15: {=IFERROR(INDEX('EQUIPAMENTOS_EFICIENTES (BDD)'!K:K,MATCH(1,('EQUIPAMENTOS_EFICIENTES (BDD)'!G:G=E15)*('EQUIPAMENTOS_EFICIENTES (BDD)'!I:I=_xlfn.MINIFS('EQUIPAMENTOS_EFICIENTES (BDD)'!I:I,'EQUIPAMENTOS_EFICIENTES (BDD)'!G:G,E15,'EQUIPAMENTOS_EFICIENTES (BDD)'!I:I,">="&G15)),0)),"")} -> 0 | AA15: =I15 -> 0 | AB15: =IF(Y15=0,0,((X15*0.293*AA15)/(1000*Y15))) -> 0 | AC15: =K15 -> 0.7 | AD15: =AB15*AC15 -> 0 | AE15: =M15 -> 0 | AF15: =N15 -> 0 | AG15: =O15 -> 0 | AH15: =Q15 -> 21.25 | AI15: =R15 -> 0 | AJ15: =S15 -> 0 | AK15: =AD15*AF15/1000 -> 0 | AL15: =AJ15*AD15 -> 0 | AM15: =U15-AL15 -> 0 | AN15: =T15-AK15 -> 0 | AO15: =IF(AN15<>0,Z15*AA15,0) -> 0 | AP15: =AN15/478.332 -> 0 | AQ15: =T15*0.9 -> 0 | AR15: =AK15*0.9 -> 0
... A44: =IF(UC_DADOS!$B$2=0,"",UC_DADOS!$B$2) -> #N/A | J44: =IF(H44=0,0,((G44*0.293*I44)/(1000*H44))) -> 0 | K44: 0.7 | L44: =J44*K44 -> 0 | N44: =M44*O44*Q44 -> 0 | Q44: 21.25 | S44: =O44*Q44*R44/765 -> 0 | T44: =N44*L44/1000 -> 0 | U44: =S44*L44 -> 0 | V44: {=IF(F44="A",E44,IFERROR(INDEX('EQUIPAMENTOS_EFICIENTES (BDD)'!G:G,MATCH(1,('EQUIPAMENTOS_EFICIENTES (BDD)'!G:G=E44)*('EQUIPAMENTOS_EFICIENTES (BDD)'!I:I=_xlfn.MINIFS('EQUIPAMENTOS_EFICIENTES (BDD)'!I:I,'EQUIPAMENTOS_EFICIENTES (BDD)'!G:G,E44,'EQUIPAMENTOS_EFICIENTES (BDD)'!I:I,">="&G44)),0)),"Substituição não encontrada"))} -> 0 | W44: {=IF(F44="A",F44,IFERROR(INDEX('EQUIPAMENTOS_EFICIENTES (BDD)'!H:H,MATCH(1,('EQUIPAMENTOS_EFICIENTES (BDD)'!G:G=E44)*('EQUIPAMENTOS_EFICIENTES (BDD)'!I:I=_xlfn.MINIFS('EQUIPAMENTOS_EFICIENTES (BDD)'!I:I,'EQUIPAMENTOS_EFICIENTES (BDD)'!G:G,E44,'EQUIPAMENTOS_EFICIENTES (BDD)'!I:I,">="&G44)),0)),"Substituição não encontrada"))} -> 0 | X44: {=IF(F44="A",G44,IFERROR(INDEX('EQUIPAMENTOS_EFICIENTES (BDD)'!I:I,MATCH(1,('EQUIPAMENTOS_EFICIENTES (BDD)'!G:G=E44)*('EQUIPAMENTOS_EFICIENTES (BDD)'!I:I=_xlfn.MINIFS('EQUIPAMENTOS_EFICIENTES (BDD)'!I:I,'EQUIPAMENTOS_EFICIENTES (BDD)'!G:G,E44,'EQUIPAMENTOS_EFICIENTES (BDD)'!I:I,">="&G44)),0)),"Substituição não encontrada"))} -> 0 | Y44: {=IF(F44="A",H44,IFERROR(INDEX('EQUIPAMENTOS_EFICIENTES (BDD)'!J:J,MATCH(1,('EQUIPAMENTOS_EFICIENTES (BDD)'!G:G=E44)*('EQUIPAMENTOS_EFICIENTES (BDD)'!I:I=_xlfn.MINIFS('EQUIPAMENTOS_EFICIENTES (BDD)'!I:I,'EQUIPAMENTOS_EFICIENTES (BDD)'!G:G,E44,'EQUIPAMENTOS_EFICIENTES (BDD)'!I:I,">="&G44)),0)),"Substituição não encontrada"))} -> 0 | Z44: {=IFERROR(INDEX('EQUIPAMENTOS_EFICIENTES (BDD)'!K:K,MATCH(1,('EQUIPAMENTOS_EFICIENTES (BDD)'!G:G=E44)*('EQUIPAMENTOS_EFICIENTES (BDD)'!I:I=_xlfn.MINIFS('EQUIPAMENTOS_EFICIENTES (BDD)'!I:I,'EQUIPAMENTOS_EFICIENTES (BDD)'!G:G,E44,'EQUIPAMENTOS_EFICIENTES (BDD)'!I:I,">="&G44)),0)),"")} -> 0 | AA44: =I44 -> 0 | AB44: =IF(Y44=0,0,((X44*0.293*AA44)/(1000*Y44))) -> 0 | AC44: =K44 -> 0.7 | AD44: =AB44*AC44 -> 0 | AE44: =M44 -> 0 | AF44: =N44 -> 0 | AG44: =O44 -> 0 | AH44: =Q44 -> 21.25 | AI44: =R44 -> 0 | AJ44: =S44 -> 0 | AK44: =AD44*AF44/1000 -> 0 | AL44: =AJ44*AD44 -> 0 | AM44: =U44-AL44 -> 0 | AN44: =T44-AK44 -> 0 | AO44: =IF(AN44<>0,Z44*AA44,0) -> 0 | AP44: =AN44/478.332 -> 0 | AQ44: =T44*0.9 -> 0 | AR44: =AK44*0.9 -> 0
E45: TOTAL | I45: =SUM(I3:I44) -> 0 | J45: =SUM(J3:J44) -> 0 | L45: =SUM(L3:L44) -> 0 | T45: =SUM(T3:T44) -> 0 | U45: =SUM(U3:U44) -> 0 | X45: TOTAL | AA45: =SUM(AA3:AA44) -> 0 | AB45: =SUM(AB3:AB44) -> 0 | AD45: =SUM(AD3:AD44) -> 0 | AK45: =SUM(AK3:AK44) -> 0 | AL45: =SUM(AL3:AL44) -> 0 | AM45: =SUM(AM3:AM44) -> 0 | AN45: =SUM(AN3:AN44) -> 0 | AO45: =SUM(AO3:AO44) -> 0 | AP45: =SUM(AP3:AP44) -> 0 | AQ45: =SUM(AQ3:AQ44) -> 0 | AR45: =SUM(AR3:AR44) -> 0
AM123: TOTAL | AN123: =SUM(AN3:AN122) -> 0 | AP123: =SUM(AP3:AP122) -> 0

Sheet Sistemas de Iluminação
A1: Unidade Consumidora | E1: SITUAÇÃO ATUAL | T1: SISTEMA PROPOSTO | AH1: RESULTADOS ESPERADOS | AJ1: RESULTADO AUTOMAÇÃO (15%)
A2: Unidade consumidora (Número da conta contrato) | B2: Pavimento | C2: Ambiente | D2: Descrição do sistema | E2: Tipo de equipamento / tecnologia | F2: Lâmpadas | H2: Reatores | J2: Potência Instalada (kW) | K2: Funcionamento (h/dia) | L2: Funcionamento (h/ano) | M2: Meses no ano, de utilização do Sistema | N2: Dias no mês, de utilização do Sistema | O2: Dias úteis no mês, de utilização do Sistema | P2: Horas por dia, de utilização do Sistema no horário de Ponta (horas) | Q2: Fator de coincidência na ponta | R2: Energia consumida (MWh/ano) | S2: Demanda média na ponta (kW) | T2: Tipo de equipamento / tecnologia | U2: Lâmpadas | W2: Reatores | Y2: Potência Instalada (kW) | Z2: Funcionamento (h/ano) | AA2: Meses no ano, de utilização do Sistema no horário de Ponta (meses) | AB2: Dias úteis no mês, de utilização do Sistema no horário de Ponta (dias) | AC2: Horas por dia, de utilização do Sistema no horário de Ponta (horas) | AD2: Fator de coincidência na ponta | AE2: Energia consumida (MWh/ano) | AF2: Demanda média na ponta (kW) | AG2: Redução de demanda na ponta (kW) | AH2: Energia economizada (MWh/ano) | AI2: Redução de consumo proposto em relação ao consumo total da UC (%) | AJ2: Energia economizada (MWh/ano)
F3: Potência (W) | G3: Quantidade | H3: Potência (W) | I3: Quantidade | U3: Potência (W) | V3: Quantidade | W3: Potência (W) | X3: Quantidade
A4: =IF(UC_DADOS!$B$2=0,"",UC_DADOS!$B$2) -> #N/A | J4: =(F4*G4+H4*I4)/1000 -> 0 | L4: =K4*M4*N4 -> 0 | O4: 21.25 | Q4: =M4*O4*P4/765 -> 0 | R4: =J4*L4/1000 -> 0 | S4: =J4*Q4 -> 0 | T4: LED | Y4: =(U4*V4+W4*X4)/1000 -> 0 | Z4: =L4 -> 0 | AA4: =M4 -> 0 | AB4: =O4 -> 21.25 | AC4: =P4 -> 0 | AD4: =Q4 -> 0 | AE4: =Y4*Z4/1000 -> 0 | AF4: =Y4*AD4 -> 0 | AG4: =S4-AF4 -> 0 | AH4: =R4-AE4 -> 0 | AI4: =AH4/478.332 -> 0 | AJ4: =R4*0.85 -> 0
A5: =IF(UC_DADOS!$B$2=0,"",UC_DADOS!$B$2) -> #N/A | J5: =(F5*G5+H5*I5)/1000 -> 0 | L5: =K5*M5*O5 -> 0 | O5: 21.25 | Q5: =M5*O5*P5/765 -> 0 | R5: =J5*L5/1000 -> 0 | S5: =J5*Q5 -> 0 | T5: LED | Y5: =(U5*V5+W5*X5)/1000 -> 0 | Z5: =L5 -> 0 | AA5: =M5 -> 0 | AB5: =O5 -> 21.25 | AC5: =P5 -> 0 | AD5: =Q5 -> 0 | AE5: =Y5*Z5/1000 -> 0 | AF5: =Y5*AD5 -> 0 | AG5: =S5-AF5 -> 0 | AH5: =R5-AE5 -> 0 | AI5: =AH5/478.332 -> 0 | AJ5: =R5*0.85 -> 0
A6: =IF(UC_DADOS!$B$2=0,"",UC_DADOS!$B$2) -> #N/A | J6: =(F6*G6+H6*I6)/1000 -> 0 | L6: =K6*M6*O6 -> 0 | O6: 21.25 | Q6: =M6*O6*P6/765 -> 0 | R6: =J6*L6/1000 -> 0 | S6: =J6*Q6 -> 0 | T6: LED | Y6: =(U6*V6+W6*X6)/1000 -> 0 | Z6: =L6 -> 0 | AA6: =M6 -> 0 | AB6: =O6 -> 21.25 | AC6: =P6 -> 0 | AD6: =Q6 -> 0 | AE6: =Y6*Z6/1000 -> 0 | AF6: =Y6*AD6 -> 0 | AG6: =S6-AF6 -> 0 | AH6: =R6-AE6 -> 0 | AI6: =AH6/478.332 -> 0 | AJ6: =R6*0.85 -> 0
A7: =IF(UC_DADOS!$B$2=0,"",UC_DADOS!$B$2) -> #N/A | J7: =(F7*G7+H7*I7)/1000 -> 0 | L7: =K7*M7*O7 -> 0 | O7: 21.25 | Q7: =M7*O7*P7/765 -> 0 | R7: =J7*L7/1000 -> 0 | S7: =J7*Q7 -> 0 | T7: LED | Y7: =(U7*V7+W7*X7)/1000 -> 0 | Z7: =L7 -> 0 | AA7: =M7 -> 0 | AB7: =O7 -> 21.25 | AC7: =P7 -> 0 | AD7: =Q7 -> 0 | AE7: =Y7*Z7/1000 -> 0 | AF7: =Y7*AD7 -> 0 | AG7: =S7-AF7 -> 0 | AH7: =R7-AE7 -> 0 | AI7: =AH7/478.332 -> 0 | AJ7: =R7*0.85 -> 0
A8: =IF(UC_DADOS!$B$2=0,"",UC_DADOS!$B$2) -> #N/A | J8: =(F8*G8+H8*I8)/1000 -> 0 | L8: =K8*M8*O8 -> 0 | O8: 21.25 | Q8: =M8*O8*P8/765 -> 0 | R8: =J8*L8/1000 -> 0 | S8: =J8*Q8 -> 0 | T8: LED | Y8: =(U8*V8+W8*X8)/1000 -> 0 | Z8: =L8 -> 0 | AA8: =M8 -> 0 | AB8: =O8 -> 21.25 | AC8: =P8 -> 0 | AD8: =Q8 -> 0 | AE8: =Y8*Z8/1000 -> 0 | AF8: =Y8*AD8 -> 0 | AG8: =S8-AF8 -> 0 | AH8: =R8-AE8 -> 0 | AI8: =AH8/478.332 -> 0 | AJ8: =R8*0.85 -> 0
